<sdf version="1.7">
  <model name="tree">
    <link name="branch_a">
      <visual name="visual">
        <geometry>
          <cylinder>
            <radius>0.06</radius>
            <length>1</length>
          </cylinder>
        </geometry>
        <material>
          <ambient>0.3 0.15 0.15 1</ambient>
          <diffuse>0.3 0.15 0.15 1</diffuse>
          <specular>0.0 0.0 0.0 1</specular>
          <emissive>0 0 0 1</emissive>
        </material>
      </visual>
    </link>
    <link name="branch_aa">
      <pose relative_to="joint_a_aa">0 0 0.1875 0 0 0</pose>
      <visual name="visual">
        <geometry>
          <cylinder>
            <radius>0.016666666666666666</radius>
            <length>0.375</length>
          </cylinder>
        </geometry>
        <material>
          <ambient>0.3 0.15 0.15 1</ambient>
          <diffuse>0.3 0.15 0.15 1</diffuse>
          <specular>0.0 0.0 0.0 1</specular>
          <emissive>0 0 0 1</emissive>
        </material>
      </visual>
      <collision name="collision">
        <geometry>
          <cylinder>
            <radius>0.016666666666666666</radius>
            <length>0.22499999999999998</length>
          </cylinder>
        </geometry>
      </collision>
    </link>
    <joint name="joint_a_aa" type="revolute">
      <pose relative_to="branch_a">0 0 0.1875 0.456165606650471 0.7169131219322384 0</pose>
      <parent>branch_a</parent>
      <child>branch_aa</child>
      <axis>
        <xyz>1 0 0 </xyz>
        <dynamics>
          <damping>100</damping>
          <friction>0</friction>
          <spring_reference>0</spring_reference>
          <spring_stiffness>5000</spring_stiffness>
        </dynamics>
        <limit>
          <effort>0</effort>
        </limit>
      </axis>
    </joint>
    <link name="apple_aa">
      <pose relative_to="joint_aa_apple">0 0 0 0 0 0</pose>
      <visual name="apple">
        <pose>0 0 0.04 0 0 0</pose>
        <geometry>
          <sphere>
            <radius>0.03</radius>
          </sphere>
        </geometry>
        <material>
          <ambient>0.1 0.5 0.2 1</ambient>
          <diffuse>0.1 0.4 0.2 1</diffuse>
          <specular>0.2 0.4 0.1 1</specular>
          <emissive>0 0 0 1</emissive>
        </material>
      </visual>
      <visual name="stalk">
        <pose>0 0 0.005 0 0 0</pose>
        <geometry>
          <cylinder>
            <radius>0.002</radius>
            <length>0.01</length>
          </cylinder>
        </geometry>
        <material>
          <ambient>0.4 0.2 0.1 1</ambient>
          <diffuse>0.4 0.2 0.1 1</diffuse>
          <specular>0.2 0.1 0.1 1</specular>
          <emissive>0 0 0 1</emissive>
        </material>
      </visual>
      <inertial>
        <pose>0 0 0.04 0 0 0</pose>
        <mass>0.1</mass>
        <inertia>
          <ixx>0.0005</ixx>
          <ixy>0</ixy>
          <ixz>0</ixz>
          <iyy>0.0005</iyy>
          <iyz>0</iyz>
          <izz>0.0005</izz>
        </inertia>
      </inertial>
      <collision name="collision">
        <pose>0 0 0.04 0 0 0</pose>
        <geometry>
          <sphere>
            <radius>0.03</radius>
          </sphere>
        </geometry>
      </collision>
    </link>
    <joint name="joint_aa_apple" type="universal">
      <pose relative_to="branch_aa">0.016666666666666666 0 -0.0009109423904477068 0 1.5707963267948966 0</pose>
      <parent>branch_aa</parent>
      <child>apple_aa</child>
      <axis>
        <xyz>0 1 0 </xyz>
        <dynamics>
          <damping>0.001</damping>
          <friction>0</friction>
          <spring_reference>0</spring_reference>
          <spring_stiffness>0.2</spring_stiffness>
        </dynamics>
        <limit>
          <effort>0</effort>
        </limit>
      </axis>
      <axis2>
        <xyz>1 0 0 </xyz>
        <dynamics>
          <damping>0.001</damping>
          <friction>0</friction>
          <spring_reference>0</spring_reference>
          <spring_stiffness>0.2</spring_stiffness>
        </dynamics>
        <limit>
          <effort>0</effort>
        </limit>
      </axis2>
    </joint>
    <link name="branch_aaa">
      <pose relative_to="joint_aa_aaa">0 0 0.15000000000000002 0 0 0</pose>
      <visual name="visual">
        <geometry>
          <cylinder>
            <radius>0.0125</radius>
            <length>0.30000000000000004</length>
          </cylinder>
        </geometry>
        <material>
          <ambient>0.3 0.15 0.15 1</ambient>
          <diffuse>0.3 0.15 0.15 1</diffuse>
          <specular>0.0 0.0 0.0 1</specular>
          <emissive>0 0 0 1</emissive>
        </material>
      </visual>
      <collision name="collision">
        <geometry>
          <cylinder>
            <radius>0.0125</radius>
            <length>0.18000000000000002</length>
          </cylinder>
        </geometry>
      </collision>
    </link>
    <joint name="joint_aa_aaa" type="revolute">
      <pose relative_to="branch_aa">0 0 0.15000000000000002 -0.25406766899729927 0.17953710939565276 0</pose>
      <parent>branch_aa</parent>
      <child>branch_aaa</child>
      <axis>
        <xyz>1 0 0 </xyz>
        <dynamics>
          <damping>20</damping>
          <friction>0</friction>
          <spring_reference>0</spring_reference>
          <spring_stiffness>1000</spring_stiffness>
        </dynamics>
        <limit>
          <effort>0</effort>
        </limit>
      </axis>
    </joint>
    <link name="apple_aaa">
      <pose relative_to="joint_aaa_apple">0 0 0 0 0 0</pose>
      <visual name="apple">
        <pose>0 0 0.04 0 0 0</pose>
        <geometry>
          <sphere>
            <radius>0.03</radius>
          </sphere>
        </geometry>
        <material>
          <ambient>0.1 0.5 0.2 1</ambient>
          <diffuse>0.1 0.4 0.2 1</diffuse>
          <specular>0.2 0.4 0.1 1</specular>
          <emissive>0 0 0 1</emissive>
        </material>
      </visual>
      <visual name="stalk">
        <pose>0 0 0.005 0 0 0</pose>
        <geometry>
          <cylinder>
            <radius>0.002</radius>
            <length>0.01</length>
          </cylinder>
        </geometry>
        <material>
          <ambient>0.4 0.2 0.1 1</ambient>
          <diffuse>0.4 0.2 0.1 1</diffuse>
          <specular>0.2 0.1 0.1 1</specular>
          <emissive>0 0 0 1</emissive>
        </material>
      </visual>
      <inertial>
        <pose>0 0 0.04 0 0 0</pose>
        <mass>0.1</mass>
        <inertia>
          <ixx>0.0005</ixx>
          <ixy>0</ixy>
          <ixz>0</ixz>
          <iyy>0.0005</iyy>
          <iyz>0</iyz>
          <izz>0.0005</izz>
        </inertia>
      </inertial>
      <collision name="collision">
        <pose>0 0 0.04 0 0 0</pose>
        <geometry>
          <sphere>
            <radius>0.03</radius>
          </sphere>
        </geometry>
      </collision>
    </link>
    <joint name="joint_aaa_apple" type="universal">
      <pose relative_to="branch_aaa">0.0125 0 0.0014165787289441014 0 1.5707963267948966 0</pose>
      <parent>branch_aaa</parent>
      <child>apple_aaa</child>
      <axis>
        <xyz>0 1 0 </xyz>
        <dynamics>
          <damping>0.001</damping>
          <friction>0</friction>
          <spring_reference>0</spring_reference>
          <spring_stiffness>0.2</spring_stiffness>
        </dynamics>
        <limit>
          <effort>0</effort>
        </limit>
      </axis>
      <axis2>
        <xyz>1 0 0 </xyz>
        <dynamics>
          <damping>0.001</damping>
          <friction>0</friction>
          <spring_reference>0</spring_reference>
          <spring_stiffness>0.2</spring_stiffness>
        </dynamics>
        <limit>
          <effort>0</effort>
        </limit>
      </axis2>
    </joint>
    <link name="branch_aab">
      <pose relative_to="joint_aa_aab">0 0 0.15000000000000002 0 0 0</pose>
      <visual name="visual">
        <geometry>
          <cylinder>
            <radius>0.0125</radius>
            <length>0.30000000000000004</length>
          </cylinder>
        </geometry>
        <material>
          <ambient>0.3 0.15 0.15 1</ambient>
          <diffuse>0.3 0.15 0.15 1</diffuse>
          <specular>0.0 0.0 0.0 1</specular>
          <emissive>0 0 0 1</emissive>
        </material>
      </visual>
      <collision name="collision">
        <geometry>
          <cylinder>
            <radius>0.0125</radius>
            <length>0.18000000000000002</length>
          </cylinder>
        </geometry>
      </collision>
    </link>
    <joint name="joint_aa_aab" type="revolute">
      <pose relative_to="branch_aa">0 0 0.15000000000000002 0.5527550517278128 -0.32842975361594434 0</pose>
      <parent>branch_aa</parent>
      <child>branch_aab</child>
      <axis>
        <xyz>1 0 0 </xyz>
        <dynamics>
          <damping>20</damping>
          <friction>0</friction>
          <spring_reference>0</spring_reference>
          <spring_stiffness>1000</spring_stiffness>
        </dynamics>
        <limit>
          <effort>0</effort>
        </limit>
      </axis>
    </joint>
    <link name="apple_aab">
      <pose relative_to="joint_aab_apple">0 0 0 0 0 0</pose>
      <visual name="apple">
        <pose>0 0 0.04 0 0 0</pose>
        <geometry>
          <sphere>
            <radius>0.03</radius>
          </sphere>
        </geometry>
        <material>
          <ambient>0.1 0.5 0.2 1</ambient>
          <diffuse>0.1 0.4 0.2 1</diffuse>
          <specular>0.2 0.4 0.1 1</specular>
          <emissive>0 0 0 1</emissive>
        </material>
      </visual>
      <visual name="stalk">
        <pose>0 0 0.005 0 0 0</pose>
        <geometry>
          <cylinder>
            <radius>0.002</radius>
            <length>0.01</length>
          </cylinder>
        </geometry>
        <material>
          <ambient>0.4 0.2 0.1 1</ambient>
          <diffuse>0.4 0.2 0.1 1</diffuse>
          <specular>0.2 0.1 0.1 1</specular>
          <emissive>0 0 0 1</emissive>
        </material>
      </visual>
      <inertial>
        <pose>0 0 0.04 0 0 0</pose>
        <mass>0.1</mass>
        <inertia>
          <ixx>0.0005</ixx>
          <ixy>0</ixy>
          <ixz>0</ixz>
          <iyy>0.0005</iyy>
          <iyz>0</iyz>
          <izz>0.0005</izz>
        </inertia>
      </inertial>
      <collision name="collision">
        <pose>0 0 0.04 0 0 0</pose>
        <geometry>
          <sphere>
            <radius>0.03</radius>
          </sphere>
        </geometry>
      </collision>
    </link>
    <joint name="joint_aab_apple" type="universal">
      <pose relative_to="branch_aab">0.0125 0 0.02094877454291482 0 1.5707963267948966 0</pose>
      <parent>branch_aab</parent>
      <child>apple_aab</child>
      <axis>
        <xyz>0 1 0 </xyz>
        <dynamics>
          <damping>0.001</damping>
          <friction>0</friction>
          <spring_reference>0</spring_reference>
          <spring_stiffness>0.2</spring_stiffness>
        </dynamics>
        <limit>
          <effort>0</effort>
        </limit>
      </axis>
      <axis2>
        <xyz>1 0 0 </xyz>
        <dynamics>
          <damping>0.001</damping>
          <friction>0</friction>
          <spring_reference>0</spring_reference>
          <spring_stiffness>0.2</spring_stiffness>
        </dynamics>
        <limit>
          <effort>0</effort>
        </limit>
      </axis2>
    </joint>
    <link name="branch_aac">
      <pose relative_to="joint_aa_aac">0 0 0.15000000000000002 0 0 0</pose>
      <visual name="visual">
        <geometry>
          <cylinder>
            <radius>0.0125</radius>
            <length>0.30000000000000004</length>
          </cylinder>
        </geometry>
        <material>
          <ambient>0.3 0.15 0.15 1</ambient>
          <diffuse>0.3 0.15 0.15 1</diffuse>
          <specular>0.0 0.0 0.0 1</specular>
          <emissive>0 0 0 1</emissive>
        </material>
      </visual>
      <collision name="collision">
        <geometry>
          <cylinder>
            <radius>0.0125</radius>
            <length>0.18000000000000002</length>
          </cylinder>
        </geometry>
      </collision>
    </link>
    <joint name="joint_aa_aac" type="revolute">
      <pose relative_to="branch_aa">0 0 0.15000000000000002 -0.34027682946392435 -0.027852996607815317 0</pose>
      <parent>branch_aa</parent>
      <child>branch_aac</child>
      <axis>
        <xyz>1 0 0 </xyz>
        <dynamics>
          <damping>20</damping>
          <friction>0</friction>
          <spring_reference>0</spring_reference>
          <spring_stiffness>1000</spring_stiffness>
        </dynamics>
        <limit>
          <effort>0</effort>
        </limit>
      </axis>
    </joint>
    <link name="apple_aac">
      <pose relative_to="joint_aac_apple">0 0 0 0 0 0</pose>
      <visual name="apple">
        <pose>0 0 0.04 0 0 0</pose>
        <geometry>
          <sphere>
            <radius>0.03</radius>
          </sphere>
        </geometry>
        <material>
          <ambient>0.1 0.5 0.2 1</ambient>
          <diffuse>0.1 0.4 0.2 1</diffuse>
          <specular>0.2 0.4 0.1 1</specular>
          <emissive>0 0 0 1</emissive>
        </material>
      </visual>
      <visual name="stalk">
        <pose>0 0 0.005 0 0 0</pose>
        <geometry>
          <cylinder>
            <radius>0.002</radius>
            <length>0.01</length>
          </cylinder>
        </geometry>
        <material>
          <ambient>0.4 0.2 0.1 1</ambient>
          <diffuse>0.4 0.2 0.1 1</diffuse>
          <specular>0.2 0.1 0.1 1</specular>
          <emissive>0 0 0 1</emissive>
        </material>
      </visual>
      <inertial>
        <pose>0 0 0.04 0 0 0</pose>
        <mass>0.1</mass>
        <inertia>
          <ixx>0.0005</ixx>
          <ixy>0</ixy>
          <ixz>0</ixz>
          <iyy>0.0005</iyy>
          <iyz>0</iyz>
          <izz>0.0005</izz>
        </inertia>
      </inertial>
      <collision name="collision">
        <pose>0 0 0.04 0 0 0</pose>
        <geometry>
          <sphere>
            <radius>0.03</radius>
          </sphere>
        </geometry>
      </collision>
    </link>
    <joint name="joint_aac_apple" type="universal">
      <pose relative_to="branch_aac">0.0125 0 -0.029427986124209014 0 1.5707963267948966 0</pose>
      <parent>branch_aac</parent>
      <child>apple_aac</child>
      <axis>
        <xyz>0 1 0 </xyz>
        <dynamics>
          <damping>0.001</damping>
          <friction>0</friction>
          <spring_reference>0</spring_reference>
          <spring_stiffness>0.2</spring_stiffness>
        </dynamics>
        <limit>
          <effort>0</effort>
        </limit>
      </axis>
      <axis2>
        <xyz>1 0 0 </xyz>
        <dynamics>
          <damping>0.001</damping>
          <friction>0</friction>
          <spring_reference>0</spring_reference>
          <spring_stiffness>0.2</spring_stiffness>
        </dynamics>
        <limit>
          <effort>0</effort>
        </limit>
      </axis2>
    </joint>
    <link name="branch_ab">
      <pose relative_to="joint_a_ab">0 0 0.1875 0 0 0</pose>
      <visual name="visual">
        <geometry>
          <cylinder>
            <radius>0.016666666666666666</radius>
            <length>0.375</length>
          </cylinder>
        </geometry>
        <material>
          <ambient>0.3 0.15 0.15 1</ambient>
          <diffuse>0.3 0.15 0.15 1</diffuse>
          <specular>0.0 0.0 0.0 1</specular>
          <emissive>0 0 0 1</emissive>
        </material>
      </visual>
      <collision name="collision">
        <geometry>
          <cylinder>
            <radius>0.016666666666666666</radius>
            <length>0.22499999999999998</length>
          </cylinder>
        </geometry>
      </collision>
    </link>
    <joint name="joint_a_ab" type="revolute">
      <pose relative_to="branch_a">0 0 0.1875 0.14633382379113746 -0.1871662754312874 0</pose>
      <parent>branch_a</parent>
      <child>branch_ab</child>
      <axis>
        <xyz>1 0 0 </xyz>
        <dynamics>
          <damping>100</damping>
          <friction>0</friction>
          <spring_reference>0</spring_reference>
          <spring_stiffness>5000</spring_stiffness>
        </dynamics>
        <limit>
          <effort>0</effort>
        </limit>
      </axis>
    </joint>
    <link name="apple_ab">
      <pose relative_to="joint_ab_apple">0 0 0 0 0 0</pose>
      <visual name="apple">
        <pose>0 0 0.04 0 0 0</pose>
        <geometry>
          <sphere>
            <radius>0.03</radius>
          </sphere>
        </geometry>
        <material>
          <ambient>0.1 0.5 0.2 1</ambient>
          <diffuse>0.1 0.4 0.2 1</diffuse>
          <specular>0.2 0.4 0.1 1</specular>
          <emissive>0 0 0 1</emissive>
        </material>
      </visual>
      <visual name="stalk">
        <pose>0 0 0.005 0 0 0</pose>
        <geometry>
          <cylinder>
            <radius>0.002</radius>
            <length>0.01</length>
          </cylinder>
        </geometry>
        <material>
          <ambient>0.4 0.2 0.1 1</ambient>
          <diffuse>0.4 0.2 0.1 1</diffuse>
          <specular>0.2 0.1 0.1 1</specular>
          <emissive>0 0 0 1</emissive>
        </material>
      </visual>
      <inertial>
        <pose>0 0 0.04 0 0 0</pose>
        <mass>0.1</mass>
        <inertia>
          <ixx>0.0005</ixx>
          <ixy>0</ixy>
          <ixz>0</ixz>
          <iyy>0.0005</iyy>
          <iyz>0</iyz>
          <izz>0.0005</izz>
        </inertia>
      </inertial>
      <collision name="collision">
        <pose>0 0 0.04 0 0 0</pose>
        <geometry>
          <sphere>
            <radius>0.03</radius>
          </sphere>
        </geometry>
      </collision>
    </link>
    <joint name="joint_ab_apple" type="universal">
      <pose relative_to="branch_ab">0.016666666666666666 0 0.03250331709315653 0 1.5707963267948966 0</pose>
      <parent>branch_ab</parent>
      <child>apple_ab</child>
      <axis>
        <xyz>0 1 0 </xyz>
        <dynamics>
          <damping>0.001</damping>
          <friction>0</friction>
          <spring_reference>0</spring_reference>
          <spring_stiffness>0.2</spring_stiffness>
        </dynamics>
        <limit>
          <effort>0</effort>
        </limit>
      </axis>
      <axis2>
        <xyz>1 0 0 </xyz>
        <dynamics>
          <damping>0.001</damping>
          <friction>0</friction>
          <spring_reference>0</spring_reference>
          <spring_stiffness>0.2</spring_stiffness>
        </dynamics>
        <limit>
          <effort>0</effort>
        </limit>
      </axis2>
    </joint>
    <link name="branch_aba">
      <pose relative_to="joint_ab_aba">0 0 0.15000000000000002 0 0 0</pose>
      <visual name="visual">
        <geometry>
          <cylinder>
            <radius>0.0125</radius>
            <length>0.30000000000000004</length>
          </cylinder>
        </geometry>
        <material>
          <ambient>0.3 0.15 0.15 1</ambient>
          <diffuse>0.3 0.15 0.15 1</diffuse>
          <specular>0.0 0.0 0.0 1</specular>
          <emissive>0 0 0 1</emissive>
        </material>
      </visual>
      <collision name="collision">
        <geometry>
          <cylinder>
            <radius>0.0125</radius>
            <length>0.18000000000000002</length>
          </cylinder>
        </geometry>
      </collision>
    </link>
    <joint name="joint_ab_aba" type="revolute">
      <pose relative_to="branch_ab">0 0 0.15000000000000002 0.09051149724497409 0.23239033370226064 0</pose>
      <parent>branch_ab</parent>
      <child>branch_aba</child>
      <axis>
        <xyz>1 0 0 </xyz>
        <dynamics>
          <damping>20</damping>
          <friction>0</friction>
          <spring_reference>0</spring_reference>
          <spring_stiffness>1000</spring_stiffness>
        </dynamics>
        <limit>
          <effort>0</effort>
        </limit>
      </axis>
    </joint>
    <link name="apple_aba">
      <pose relative_to="joint_aba_apple">0 0 0 0 0 0</pose>
      <visual name="apple">
        <pose>0 0 0.04 0 0 0</pose>
        <geometry>
          <sphere>
            <radius>0.03</radius>
          </sphere>
        </geometry>
        <material>
          <ambient>0.1 0.5 0.2 1</ambient>
          <diffuse>0.1 0.4 0.2 1</diffuse>
          <specular>0.2 0.4 0.1 1</specular>
          <emissive>0 0 0 1</emissive>
        </material>
      </visual>
      <visual name="stalk">
        <pose>0 0 0.005 0 0 0</pose>
        <geometry>
          <cylinder>
            <radius>0.002</radius>
            <length>0.01</length>
          </cylinder>
        </geometry>
        <material>
          <ambient>0.4 0.2 0.1 1</ambient>
          <diffuse>0.4 0.2 0.1 1</diffuse>
          <specular>0.2 0.1 0.1 1</specular>
          <emissive>0 0 0 1</emissive>
        </material>
      </visual>
      <inertial>
        <pose>0 0 0.04 0 0 0</pose>
        <mass>0.1</mass>
        <inertia>
          <ixx>0.0005</ixx>
          <ixy>0</ixy>
          <ixz>0</ixz>
          <iyy>0.0005</iyy>
          <iyz>0</iyz>
          <izz>0.0005</izz>
        </inertia>
      </inertial>
      <collision name="collision">
        <pose>0 0 0.04 0 0 0</pose>
        <geometry>
          <sphere>
            <radius>0.03</radius>
          </sphere>
        </geometry>
      </collision>
    </link>
    <joint name="joint_aba_apple" type="universal">
      <pose relative_to="branch_aba">0.0125 0 0.0317532702941579 0 1.5707963267948966 0</pose>
      <parent>branch_aba</parent>
      <child>apple_aba</child>
      <axis>
        <xyz>0 1 0 </xyz>
        <dynamics>
          <damping>0.001</damping>
          <friction>0</friction>
          <spring_reference>0</spring_reference>
          <spring_stiffness>0.2</spring_stiffness>
        </dynamics>
        <limit>
          <effort>0</effort>
        </limit>
      </axis>
      <axis2>
        <xyz>1 0 0 </xyz>
        <dynamics>
          <damping>0.001</damping>
          <friction>0</friction>
          <spring_reference>0</spring_reference>
          <spring_stiffness>0.2</spring_stiffness>
        </dynamics>
        <limit>
          <effort>0</effort>
        </limit>
      </axis2>
    </joint>
    <link name="branch_abb">
      <pose relative_to="joint_ab_abb">0 0 0.15000000000000002 0 0 0</pose>
      <visual name="visual">
        <geometry>
          <cylinder>
            <radius>0.0125</radius>
            <length>0.30000000000000004</length>
          </cylinder>
        </geometry>
        <material>
          <ambient>0.3 0.15 0.15 1</ambient>
          <diffuse>0.3 0.15 0.15 1</diffuse>
          <specular>0.0 0.0 0.0 1</specular>
          <emissive>0 0 0 1</emissive>
        </material>
      </visual>
      <collision name="collision">
        <geometry>
          <cylinder>
            <radius>0.0125</radius>
            <length>0.18000000000000002</length>
          </cylinder>
        </geometry>
      </collision>
    </link>
    <joint name="joint_ab_abb" type="revolute">
      <pose relative_to="branch_ab">0 0 0.15000000000000002 0.4030780283075468 -0.24377228813874208 0</pose>
      <parent>branch_ab</parent>
      <child>branch_abb</child>
      <axis>
        <xyz>1 0 0 </xyz>
        <dynamics>
          <damping>20</damping>
          <friction>0</friction>
          <spring_reference>0</spring_reference>
          <spring_stiffness>1000</spring_stiffness>
        </dynamics>
        <limit>
          <effort>0</effort>
        </limit>
      </axis>
    </joint>
    <link name="apple_abb">
      <pose relative_to="joint_abb_apple">0 0 0 0 0 0</pose>
      <visual name="apple">
        <pose>0 0 0.04 0 0 0</pose>
        <geometry>
          <sphere>
            <radius>0.03</radius>
          </sphere>
        </geometry>
        <material>
          <ambient>0.1 0.5 0.2 1</ambient>
          <diffuse>0.1 0.4 0.2 1</diffuse>
          <specular>0.2 0.4 0.1 1</specular>
          <emissive>0 0 0 1</emissive>
        </material>
      </visual>
      <visual name="stalk">
        <pose>0 0 0.005 0 0 0</pose>
        <geometry>
          <cylinder>
            <radius>0.002</radius>
            <length>0.01</length>
          </cylinder>
        </geometry>
        <material>
          <ambient>0.4 0.2 0.1 1</ambient>
          <diffuse>0.4 0.2 0.1 1</diffuse>
          <specular>0.2 0.1 0.1 1</specular>
          <emissive>0 0 0 1</emissive>
        </material>
      </visual>
      <inertial>
        <pose>0 0 0.04 0 0 0</pose>
        <mass>0.1</mass>
        <inertia>
          <ixx>0.0005</ixx>
          <ixy>0</ixy>
          <ixz>0</ixz>
          <iyy>0.0005</iyy>
          <iyz>0</iyz>
          <izz>0.0005</izz>
        </inertia>
      </inertial>
      <collision name="collision">
        <pose>0 0 0.04 0 0 0</pose>
        <geometry>
          <sphere>
            <radius>0.03</radius>
          </sphere>
        </geometry>
      </collision>
    </link>
    <joint name="joint_abb_apple" type="universal">
      <pose relative_to="branch_abb">0.0125 0 0.06834990628128519 0 1.5707963267948966 0</pose>
      <parent>branch_abb</parent>
      <child>apple_abb</child>
      <axis>
        <xyz>0 1 0 </xyz>
        <dynamics>
          <damping>0.001</damping>
          <friction>0</friction>
          <spring_reference>0</spring_reference>
          <spring_stiffness>0.2</spring_stiffness>
        </dynamics>
        <limit>
          <effort>0</effort>
        </limit>
      </axis>
      <axis2>
        <xyz>1 0 0 </xyz>
        <dynamics>
          <damping>0.001</damping>
          <friction>0</friction>
          <spring_reference>0</spring_reference>
          <spring_stiffness>0.2</spring_stiffness>
        </dynamics>
        <limit>
          <effort>0</effort>
        </limit>
      </axis2>
    </joint>
    <link name="branch_abc">
      <pose relative_to="joint_ab_abc">0 0 0.15000000000000002 0 0 0</pose>
      <visual name="visual">
        <geometry>
          <cylinder>
            <radius>0.0125</radius>
            <length>0.30000000000000004</length>
          </cylinder>
        </geometry>
        <material>
          <ambient>0.3 0.15 0.15 1</ambient>
          <diffuse>0.3 0.15 0.15 1</diffuse>
          <specular>0.0 0.0 0.0 1</specular>
          <emissive>0 0 0 1</emissive>
        </material>
      </visual>
      <collision name="collision">
        <geometry>
          <cylinder>
            <radius>0.0125</radius>
            <length>0.18000000000000002</length>
          </cylinder>
        </geometry>
      </collision>
    </link>
    <joint name="joint_ab_abc" type="revolute">
      <pose relative_to="branch_ab">0 0 0.15000000000000002 0.21411776494064044 0.020931116621197232 0</pose>
      <parent>branch_ab</parent>
      <child>branch_abc</child>
      <axis>
        <xyz>1 0 0 </xyz>
        <dynamics>
          <damping>20</damping>
          <friction>0</friction>
          <spring_reference>0</spring_reference>
          <spring_stiffness>1000</spring_stiffness>
        </dynamics>
        <limit>
          <effort>0</effort>
        </limit>
      </axis>
    </joint>
    <link name="apple_abc">
      <pose relative_to="joint_abc_apple">0 0 0 0 0 0</pose>
      <visual name="apple">
        <pose>0 0 0.04 0 0 0</pose>
        <geometry>
          <sphere>
            <radius>0.03</radius>
          </sphere>
        </geometry>
        <material>
          <ambient>0.1 0.5 0.2 1</ambient>
          <diffuse>0.1 0.4 0.2 1</diffuse>
          <specular>0.2 0.4 0.1 1</specular>
          <emissive>0 0 0 1</emissive>
        </material>
      </visual>
      <visual name="stalk">
        <pose>0 0 0.005 0 0 0</pose>
        <geometry>
          <cylinder>
            <radius>0.002</radius>
            <length>0.01</length>
          </cylinder>
        </geometry>
        <material>
          <ambient>0.4 0.2 0.1 1</ambient>
          <diffuse>0.4 0.2 0.1 1</diffuse>
          <specular>0.2 0.1 0.1 1</specular>
          <emissive>0 0 0 1</emissive>
        </material>
      </visual>
      <inertial>
        <pose>0 0 0.04 0 0 0</pose>
        <mass>0.1</mass>
        <inertia>
          <ixx>0.0005</ixx>
          <ixy>0</ixy>
          <ixz>0</ixz>
          <iyy>0.0005</iyy>
          <iyz>0</iyz>
          <izz>0.0005</izz>
        </inertia>
      </inertial>
      <collision name="collision">
        <pose>0 0 0.04 0 0 0</pose>
        <geometry>
          <sphere>
            <radius>0.03</radius>
          </sphere>
        </geometry>
      </collision>
    </link>
    <joint name="joint_abc_apple" type="universal">
      <pose relative_to="branch_abc">0.0125 0 -0.015838286491035254 0 1.5707963267948966 0</pose>
      <parent>branch_abc</parent>
      <child>apple_abc</child>
      <axis>
        <xyz>0 1 0 </xyz>
        <dynamics>
          <damping>0.001</damping>
          <friction>0</friction>
          <spring_reference>0</spring_reference>
          <spring_stiffness>0.2</spring_stiffness>
        </dynamics>
        <limit>
          <effort>0</effort>
        </limit>
      </axis>
      <axis2>
        <xyz>1 0 0 </xyz>
        <dynamics>
          <damping>0.001</damping>
          <friction>0</friction>
          <spring_reference>0</spring_reference>
          <spring_stiffness>0.2</spring_stiffness>
        </dynamics>
        <limit>
          <effort>0</effort>
        </limit>
      </axis2>
    </joint>
    <link name="branch_ac">
      <pose relative_to="joint_a_ac">0 0 0.1875 0 0 0</pose>
      <visual name="visual">
        <geometry>
          <cylinder>
            <radius>0.016666666666666666</radius>
            <length>0.375</length>
          </cylinder>
        </geometry>
        <material>
          <ambient>0.3 0.15 0.15 1</ambient>
          <diffuse>0.3 0.15 0.15 1</diffuse>
          <specular>0.0 0.0 0.0 1</specular>
          <emissive>0 0 0 1</emissive>
        </material>
      </visual>
      <collision name="collision">
        <geometry>
          <cylinder>
            <radius>0.016666666666666666</radius>
            <length>0.22499999999999998</length>
          </cylinder>
        </geometry>
      </collision>
    </link>
    <joint name="joint_a_ac" type="revolute">
      <pose relative_to="branch_a">0 0 0.1875 0.3444847805953981 0.47259824683709406 0</pose>
      <parent>branch_a</parent>
      <child>branch_ac</child>
      <axis>
        <xyz>1 0 0 </xyz>
        <dynamics>
          <damping>100</damping>
          <friction>0</friction>
          <spring_reference>0</spring_reference>
          <spring_stiffness>5000</spring_stiffness>
        </dynamics>
        <limit>
          <effort>0</effort>
        </limit>
      </axis>
    </joint>
    <link name="apple_ac">
      <pose relative_to="joint_ac_apple">0 0 0 0 0 0</pose>
      <visual name="apple">
        <pose>0 0 0.04 0 0 0</pose>
        <geometry>
          <sphere>
            <radius>0.03</radius>
          </sphere>
        </geometry>
        <material>
          <ambient>0.1 0.5 0.2 1</ambient>
          <diffuse>0.1 0.4 0.2 1</diffuse>
          <specular>0.2 0.4 0.1 1</specular>
          <emissive>0 0 0 1</emissive>
        </material>
      </visual>
      <visual name="stalk">
        <pose>0 0 0.005 0 0 0</pose>
        <geometry>
          <cylinder>
            <radius>0.002</radius>
            <length>0.01</length>
          </cylinder>
        </geometry>
        <material>
          <ambient>0.4 0.2 0.1 1</ambient>
          <diffuse>0.4 0.2 0.1 1</diffuse>
          <specular>0.2 0.1 0.1 1</specular>
          <emissive>0 0 0 1</emissive>
        </material>
      </visual>
      <inertial>
        <pose>0 0 0.04 0 0 0</pose>
        <mass>0.1</mass>
        <inertia>
          <ixx>0.0005</ixx>
          <ixy>0</ixy>
          <ixz>0</ixz>
          <iyy>0.0005</iyy>
          <iyz>0</iyz>
          <izz>0.0005</izz>
        </inertia>
      </inertial>
      <collision name="collision">
        <pose>0 0 0.04 0 0 0</pose>
        <geometry>
          <sphere>
            <radius>0.03</radius>
          </sphere>
        </geometry>
      </collision>
    </link>
    <joint name="joint_ac_apple" type="universal">
      <pose relative_to="branch_ac">0.016666666666666666 0 0.03651704791661965 0 1.5707963267948966 0</pose>
      <parent>branch_ac</parent>
      <child>apple_ac</child>
      <axis>
        <xyz>0 1 0 </xyz>
        <dynamics>
          <damping>0.001</damping>
          <friction>0</friction>
          <spring_reference>0</spring_reference>
          <spring_stiffness>0.2</spring_stiffness>
        </dynamics>
        <limit>
          <effort>0</effort>
        </limit>
      </axis>
      <axis2>
        <xyz>1 0 0 </xyz>
        <dynamics>
          <damping>0.001</damping>
          <friction>0</friction>
          <spring_reference>0</spring_reference>
          <spring_stiffness>0.2</spring_stiffness>
        </dynamics>
        <limit>
          <effort>0</effort>
        </limit>
      </axis2>
    </joint>
    <link name="branch_aca">
      <pose relative_to="joint_ac_aca">0 0 0.15000000000000002 0 0 0</pose>
      <visual name="visual">
        <geometry>
          <cylinder>
            <radius>0.0125</radius>
            <length>0.30000000000000004</length>
          </cylinder>
        </geometry>
        <material>
          <ambient>0.3 0.15 0.15 1</ambient>
          <diffuse>0.3 0.15 0.15 1</diffuse>
          <specular>0.0 0.0 0.0 1</specular>
          <emissive>0 0 0 1</emissive>
        </material>
      </visual>
      <collision name="collision">
        <geometry>
          <cylinder>
            <radius>0.0125</radius>
            <length>0.18000000000000002</length>
          </cylinder>
        </geometry>
      </collision>
    </link>
    <joint name="joint_ac_aca" type="revolute">
      <pose relative_to="branch_ac">0 0 0.15000000000000002 0.5881741882451541 -0.5217162510951158 0</pose>
      <parent>branch_ac</parent>
      <child>branch_aca</child>
      <axis>
        <xyz>1 0 0 </xyz>
        <dynamics>
          <damping>20</damping>
          <friction>0</friction>
          <spring_reference>0</spring_reference>
          <spring_stiffness>1000</spring_stiffness>
        </dynamics>
        <limit>
          <effort>0</effort>
        </limit>
      </axis>
    </joint>
    <link name="apple_aca">
      <pose relative_to="joint_aca_apple">0 0 0 0 0 0</pose>
      <visual name="apple">
        <pose>0 0 0.04 0 0 0</pose>
        <geometry>
          <sphere>
            <radius>0.03</radius>
          </sphere>
        </geometry>
        <material>
          <ambient>0.1 0.5 0.2 1</ambient>
          <diffuse>0.1 0.4 0.2 1</diffuse>
          <specular>0.2 0.4 0.1 1</specular>
          <emissive>0 0 0 1</emissive>
        </material>
      </visual>
      <visual name="stalk">
        <pose>0 0 0.005 0 0 0</pose>
        <geometry>
          <cylinder>
            <radius>0.002</radius>
            <length>0.01</length>
          </cylinder>
        </geometry>
        <material>
          <ambient>0.4 0.2 0.1 1</ambient>
          <diffuse>0.4 0.2 0.1 1</diffuse>
          <specular>0.2 0.1 0.1 1</specular>
          <emissive>0 0 0 1</emissive>
        </material>
      </visual>
      <inertial>
        <pose>0 0 0.04 0 0 0</pose>
        <mass>0.1</mass>
        <inertia>
          <ixx>0.0005</ixx>
          <ixy>0</ixy>
          <ixz>0</ixz>
          <iyy>0.0005</iyy>
          <iyz>0</iyz>
          <izz>0.0005</izz>
        </inertia>
      </inertial>
      <collision name="collision">
        <pose>0 0 0.04 0 0 0</pose>
        <geometry>
          <sphere>
            <radius>0.03</radius>
          </sphere>
        </geometry>
      </collision>
    </link>
    <joint name="joint_aca_apple" type="universal">
      <pose relative_to="branch_aca">0.0125 0 -0.04316350487978475 0 1.5707963267948966 0</pose>
      <parent>branch_aca</parent>
      <child>apple_aca</child>
      <axis>
        <xyz>0 1 0 </xyz>
        <dynamics>
          <damping>0.001</damping>
          <friction>0</friction>
          <spring_reference>0</spring_reference>
          <spring_stiffness>0.2</spring_stiffness>
        </dynamics>
        <limit>
          <effort>0</effort>
        </limit>
      </axis>
      <axis2>
        <xyz>1 0 0 </xyz>
        <dynamics>
          <damping>0.001</damping>
          <friction>0</friction>
          <spring_reference>0</spring_reference>
          <spring_stiffness>0.2</spring_stiffness>
        </dynamics>
        <limit>
          <effort>0</effort>
        </limit>
      </axis2>
    </joint>
    <link name="branch_acb">
      <pose relative_to="joint_ac_acb">0 0 0.15000000000000002 0 0 0</pose>
      <visual name="visual">
        <geometry>
          <cylinder>
            <radius>0.0125</radius>
            <length>0.30000000000000004</length>
          </cylinder>
        </geometry>
        <material>
          <ambient>0.3 0.15 0.15 1</ambient>
          <diffuse>0.3 0.15 0.15 1</diffuse>
          <specular>0.0 0.0 0.0 1</specular>
          <emissive>0 0 0 1</emissive>
        </material>
      </visual>
      <collision name="collision">
        <geometry>
          <cylinder>
            <radius>0.0125</radius>
            <length>0.18000000000000002</length>
          </cylinder>
        </geometry>
      </collision>
    </link>
    <joint name="joint_ac_acb" type="revolute">
      <pose relative_to="branch_ac">0 0 0.15000000000000002 -0.36982988514509435 -0.16260397849887592 0</pose>
      <parent>branch_ac</parent>
      <child>branch_acb</child>
      <axis>
        <xyz>1 0 0 </xyz>
        <dynamics>
          <damping>20</damping>
          <friction>0</friction>
          <spring_reference>0</spring_reference>
          <spring_stiffness>1000</spring_stiffness>
        </dynamics>
        <limit>
          <effort>0</effort>
        </limit>
      </axis>
    </joint>
    <link name="apple_acb">
      <pose relative_to="joint_acb_apple">0 0 0 0 0 0</pose>
      <visual name="apple">
        <pose>0 0 0.04 0 0 0</pose>
        <geometry>
          <sphere>
            <radius>0.03</radius>
          </sphere>
        </geometry>
        <material>
          <ambient>0.1 0.5 0.2 1</ambient>
          <diffuse>0.1 0.4 0.2 1</diffuse>
          <specular>0.2 0.4 0.1 1</specular>
          <emissive>0 0 0 1</emissive>
        </material>
      </visual>
      <visual name="stalk">
        <pose>0 0 0.005 0 0 0</pose>
        <geometry>
          <cylinder>
            <radius>0.002</radius>
            <length>0.01</length>
          </cylinder>
        </geometry>
        <material>
          <ambient>0.4 0.2 0.1 1</ambient>
          <diffuse>0.4 0.2 0.1 1</diffuse>
          <specular>0.2 0.1 0.1 1</specular>
          <emissive>0 0 0 1</emissive>
        </material>
      </visual>
      <inertial>
        <pose>0 0 0.04 0 0 0</pose>
        <mass>0.1</mass>
        <inertia>
          <ixx>0.0005</ixx>
          <ixy>0</ixy>
          <ixz>0</ixz>
          <iyy>0.0005</iyy>
          <iyz>0</iyz>
          <izz>0.0005</izz>
        </inertia>
      </inertial>
      <collision name="collision">
        <pose>0 0 0.04 0 0 0</pose>
        <geometry>
          <sphere>
            <radius>0.03</radius>
          </sphere>
        </geometry>
      </collision>
    </link>
    <joint name="joint_acb_apple" type="universal">
      <pose relative_to="branch_acb">0.0125 0 -0.005340455414019075 0 1.5707963267948966 0</pose>
      <parent>branch_acb</parent>
      <child>apple_acb</child>
      <axis>
        <xyz>0 1 0 </xyz>
        <dynamics>
          <damping>0.001</damping>
          <friction>0</friction>
          <spring_reference>0</spring_reference>
          <spring_stiffness>0.2</spring_stiffness>
        </dynamics>
        <limit>
          <effort>0</effort>
        </limit>
      </axis>
      <axis2>
        <xyz>1 0 0 </xyz>
        <dynamics>
          <damping>0.001</damping>
          <friction>0</friction>
          <spring_reference>0</spring_reference>
          <spring_stiffness>0.2</spring_stiffness>
        </dynamics>
        <limit>
          <effort>0</effort>
        </limit>
      </axis2>
    </joint>
    <link name="branch_acc">
      <pose relative_to="joint_ac_acc">0 0 0.15000000000000002 0 0 0</pose>
      <visual name="visual">
        <geometry>
          <cylinder>
            <radius>0.0125</radius>
            <length>0.30000000000000004</length>
          </cylinder>
        </geometry>
        <material>
          <ambient>0.3 0.15 0.15 1</ambient>
          <diffuse>0.3 0.15 0.15 1</diffuse>
          <specular>0.0 0.0 0.0 1</specular>
          <emissive>0 0 0 1</emissive>
        </material>
      </visual>
      <collision name="collision">
        <geometry>
          <cylinder>
            <radius>0.0125</radius>
            <length>0.18000000000000002</length>
          </cylinder>
        </geometry>
      </collision>
    </link>
    <joint name="joint_ac_acc" type="revolute">
      <pose relative_to="branch_ac">0 0 0.15000000000000002 0.4983450508855823 0.41902015424294803 0</pose>
      <parent>branch_ac</parent>
      <child>branch_acc</child>
      <axis>
        <xyz>1 0 0 </xyz>
        <dynamics>
          <damping>20</damping>
          <friction>0</friction>
          <spring_reference>0</spring_reference>
          <spring_stiffness>1000</spring_stiffness>
        </dynamics>
        <limit>
          <effort>0</effort>
        </limit>
      </axis>
    </joint>
    <link name="apple_acc">
      <pose relative_to="joint_acc_apple">0 0 0 0 0 0</pose>
      <visual name="apple">
        <pose>0 0 0.04 0 0 0</pose>
        <geometry>
          <sphere>
            <radius>0.03</radius>
          </sphere>
        </geometry>
        <material>
          <ambient>0.1 0.5 0.2 1</ambient>
          <diffuse>0.1 0.4 0.2 1</diffuse>
          <specular>0.2 0.4 0.1 1</specular>
          <emissive>0 0 0 1</emissive>
        </material>
      </visual>
      <visual name="stalk">
        <pose>0 0 0.005 0 0 0</pose>
        <geometry>
          <cylinder>
            <radius>0.002</radius>
            <length>0.01</length>
          </cylinder>
        </geometry>
        <material>
          <ambient>0.4 0.2 0.1 1</ambient>
          <diffuse>0.4 0.2 0.1 1</diffuse>
          <specular>0.2 0.1 0.1 1</specular>
          <emissive>0 0 0 1</emissive>
        </material>
      </visual>
      <inertial>
        <pose>0 0 0.04 0 0 0</pose>
        <mass>0.1</mass>
        <inertia>
          <ixx>0.0005</ixx>
          <ixy>0</ixy>
          <ixz>0</ixz>
          <iyy>0.0005</iyy>
          <iyz>0</iyz>
          <izz>0.0005</izz>
        </inertia>
      </inertial>
      <collision name="collision">
        <pose>0 0 0.04 0 0 0</pose>
        <geometry>
          <sphere>
            <radius>0.03</radius>
          </sphere>
        </geometry>
      </collision>
    </link>
    <joint name="joint_acc_apple" type="universal">
      <pose relative_to="branch_acc">0.0125 0 0.07201079509189133 0 1.5707963267948966 0</pose>
      <parent>branch_acc</parent>
      <child>apple_acc</child>
      <axis>
        <xyz>0 1 0 </xyz>
        <dynamics>
          <damping>0.001</damping>
          <friction>0</friction>
          <spring_reference>0</spring_reference>
          <spring_stiffness>0.2</spring_stiffness>
        </dynamics>
        <limit>
          <effort>0</effort>
        </limit>
      </axis>
      <axis2>
        <xyz>1 0 0 </xyz>
        <dynamics>
          <damping>0.001</damping>
          <friction>0</friction>
          <spring_reference>0</spring_reference>
          <spring_stiffness>0.2</spring_stiffness>
        </dynamics>
        <limit>
          <effort>0</effort>
        </limit>
      </axis2>
    </joint>
  </model>
</sdf>