<sdf version="1.7">
  <model name="tree">
    <link name="branch_a">
      <visual name="visual">
        <geometry>
          <cylinder>
            <radius>0.06</radius>
            <length>1</length>
          </cylinder>
        </geometry>
        <material>
          <ambient>0.3 0.15 0.15 1</ambient>
          <diffuse>0.3 0.15 0.15 1</diffuse>
          <specular>0.0 0.0 0.0 1</specular>
          <emissive>0 0 0 1</emissive>
        </material>
      </visual>
    </link>
    <link name="branch_aa">
      <pose relative_to="joint_a_aa">0 0 0.1875 0 0 0</pose>
      <visual name="visual">
        <geometry>
          <cylinder>
            <radius>0.016666666666666666</radius>
            <length>0.375</length>
          </cylinder>
        </geometry>
        <material>
          <ambient>0.3 0.15 0.15 1</ambient>
          <diffuse>0.3 0.15 0.15 1</diffuse>
          <specular>0.0 0.0 0.0 1</specular>
          <emissive>0 0 0 1</emissive>
        </material>
      </visual>
      <collision name="collision">
        <geometry>
          <cylinder>
            <radius>0.016666666666666666</radius>
            <length>0.22499999999999998</length>
          </cylinder>
        </geometry>
      </collision>
    </link>
    <joint name="joint_a_aa" type="revolute">
      <pose relative_to="branch_a">0 0 0.1875 0.6006867236113684 -0.5802627107725031 0</pose>
      <parent>branch_a</parent>
      <child>branch_aa</child>
      <axis>
        <xyz>1 0 0 </xyz>
        <dynamics>
          <damping>100</damping>
          <friction>0</friction>
          <spring_reference>0</spring_reference>
          <spring_stiffness>5000</spring_stiffness>
        </dynamics>
        <limit>
          <effort>0</effort>
        </limit>
      </axis>
    </joint>
    <link name="apple_aa">
      <pose relative_to="joint_aa_apple">0 0 0 0 0 0</pose>
      <visual name="apple">
        <pose>0 0 0.04 0 0 0</pose>
        <geometry>
          <sphere>
            <radius>0.03</radius>
          </sphere>
        </geometry>
        <material>
          <ambient>0.1 0.5 0.2 1</ambient>
          <diffuse>0.1 0.4 0.2 1</diffuse>
          <specular>0.2 0.4 0.1 1</specular>
          <emissive>0 0 0 1</emissive>
        </material>
      </visual>
      <visual name="stalk">
        <pose>0 0 0.005 0 0 0</pose>
        <geometry>
          <cylinder>
            <radius>0.002</radius>
            <length>0.01</length>
          </cylinder>
        </geometry>
        <material>
          <ambient>0.4 0.2 0.1 1</ambient>
          <diffuse>0.4 0.2 0.1 1</diffuse>
          <specular>0.2 0.1 0.1 1</specular>
          <emissive>0 0 0 1</emissive>
        </material>
      </visual>
      <inertial>
        <pose>0 0 0.04 0 0 0</pose>
        <mass>0.1</mass>
        <inertia>
          <ixx>0.0005</ixx>
          <ixy>0</ixy>
          <ixz>0</ixz>
          <iyy>0.0005</iyy>
          <iyz>0</iyz>
          <izz>0.0005</izz>
        </inertia>
      </inertial>
      <collision name="collision">
        <pose>0 0 0.04 0 0 0</pose>
        <geometry>
          <sphere>
            <radius>0.03</radius>
          </sphere>
        </geometry>
      </collision>
    </link>
    <joint name="joint_aa_apple" type="universal">
      <pose relative_to="branch_aa">0.016666666666666666 0 -0.05083262908838853 0 1.5707963267948966 0</pose>
      <parent>branch_aa</parent>
      <child>apple_aa</child>
      <axis>
        <xyz>0 1 0 </xyz>
        <dynamics>
          <damping>0.001</damping>
          <friction>0</friction>
          <spring_reference>0</spring_reference>
          <spring_stiffness>0.2</spring_stiffness>
        </dynamics>
        <limit>
          <effort>0</effort>
        </limit>
      </axis>
      <axis2>
        <xyz>1 0 0 </xyz>
        <dynamics>
          <damping>0.001</damping>
          <friction>0</friction>
          <spring_reference>0</spring_reference>
          <spring_stiffness>0.2</spring_stiffness>
        </dynamics>
        <limit>
          <effort>0</effort>
        </limit>
      </axis2>
    </joint>
    <link name="branch_aaa">
      <pose relative_to="joint_aa_aaa">0 0 0.15000000000000002 0 0 0</pose>
      <visual name="visual">
        <geometry>
          <cylinder>
            <radius>0.0125</radius>
            <length>0.30000000000000004</length>
          </cylinder>
        </geometry>
        <material>
          <ambient>0.3 0.15 0.15 1</ambient>
          <diffuse>0.3 0.15 0.15 1</diffuse>
          <specular>0.0 0.0 0.0 1</specular>
          <emissive>0 0 0 1</emissive>
        </material>
      </visual>
      <collision name="collision">
        <geometry>
          <cylinder>
            <radius>0.0125</radius>
            <length>0.18000000000000002</length>
          </cylinder>
        </geometry>
      </collision>
    </link>
    <joint name="joint_aa_aaa" type="revolute">
      <pose relative_to="branch_aa">0 0 0.15000000000000002 -0.5385886643309545 -0.34359688484339596 0</pose>
      <parent>branch_aa</parent>
      <child>branch_aaa</child>
      <axis>
        <xyz>1 0 0 </xyz>
        <dynamics>
          <damping>20</damping>
          <friction>0</friction>
          <spring_reference>0</spring_reference>
          <spring_stiffness>1000</spring_stiffness>
        </dynamics>
        <limit>
          <effort>0</effort>
        </limit>
      </axis>
    </joint>
    <link name="apple_aaa">
      <pose relative_to="joint_aaa_apple">0 0 0 0 0 0</pose>
      <visual name="apple">
        <pose>0 0 0.04 0 0 0</pose>
        <geometry>
          <sphere>
            <radius>0.03</radius>
          </sphere>
        </geometry>
        <material>
          <ambient>0.1 0.5 0.2 1</ambient>
          <diffuse>0.1 0.4 0.2 1</diffuse>
          <specular>0.2 0.4 0.1 1</specular>
          <emissive>0 0 0 1</emissive>
        </material>
      </visual>
      <visual name="stalk">
        <pose>0 0 0.005 0 0 0</pose>
        <geometry>
          <cylinder>
            <radius>0.002</radius>
            <length>0.01</length>
          </cylinder>
        </geometry>
        <material>
          <ambient>0.4 0.2 0.1 1</ambient>
          <diffuse>0.4 0.2 0.1 1</diffuse>
          <specular>0.2 0.1 0.1 1</specular>
          <emissive>0 0 0 1</emissive>
        </material>
      </visual>
      <inertial>
        <pose>0 0 0.04 0 0 0</pose>
        <mass>0.1</mass>
        <inertia>
          <ixx>0.0005</ixx>
          <ixy>0</ixy>
          <ixz>0</ixz>
          <iyy>0.0005</iyy>
          <iyz>0</iyz>
          <izz>0.0005</izz>
        </inertia>
      </inertial>
      <collision name="collision">
        <pose>0 0 0.04 0 0 0</pose>
        <geometry>
          <sphere>
            <radius>0.03</radius>
          </sphere>
        </geometry>
      </collision>
    </link>
    <joint name="joint_aaa_apple" type="universal">
      <pose relative_to="branch_aaa">0.0125 0 -0.0449129484310914 0 1.5707963267948966 0</pose>
      <parent>branch_aaa</parent>
      <child>apple_aaa</child>
      <axis>
        <xyz>0 1 0 </xyz>
        <dynamics>
          <damping>0.001</damping>
          <friction>0</friction>
          <spring_reference>0</spring_reference>
          <spring_stiffness>0.2</spring_stiffness>
        </dynamics>
        <limit>
          <effort>0</effort>
        </limit>
      </axis>
      <axis2>
        <xyz>1 0 0 </xyz>
        <dynamics>
          <damping>0.001</damping>
          <friction>0</friction>
          <spring_reference>0</spring_reference>
          <spring_stiffness>0.2</spring_stiffness>
        </dynamics>
        <limit>
          <effort>0</effort>
        </limit>
      </axis2>
    </joint>
    <link name="branch_aab">
      <pose relative_to="joint_aa_aab">0 0 0.15000000000000002 0 0 0</pose>
      <visual name="visual">
        <geometry>
          <cylinder>
            <radius>0.0125</radius>
            <length>0.30000000000000004</length>
          </cylinder>
        </geometry>
        <material>
          <ambient>0.3 0.15 0.15 1</ambient>
          <diffuse>0.3 0.15 0.15 1</diffuse>
          <specular>0.0 0.0 0.0 1</specular>
          <emissive>0 0 0 1</emissive>
        </material>
      </visual>
      <collision name="collision">
        <geometry>
          <cylinder>
            <radius>0.0125</radius>
            <length>0.18000000000000002</length>
          </cylinder>
        </geometry>
      </collision>
    </link>
    <joint name="joint_aa_aab" type="revolute">
      <pose relative_to="branch_aa">0 0 0.15000000000000002 -0.2591960358030296 -0.7358628556478066 0</pose>
      <parent>branch_aa</parent>
      <child>branch_aab</child>
      <axis>
        <xyz>1 0 0 </xyz>
        <dynamics>
          <damping>20</damping>
          <friction>0</friction>
          <spring_reference>0</spring_reference>
          <spring_stiffness>1000</spring_stiffness>
        </dynamics>
        <limit>
          <effort>0</effort>
        </limit>
      </axis>
    </joint>
    <link name="apple_aab">
      <pose relative_to="joint_aab_apple">0 0 0 0 0 0</pose>
      <visual name="apple">
        <pose>0 0 0.04 0 0 0</pose>
        <geometry>
          <sphere>
            <radius>0.03</radius>
          </sphere>
        </geometry>
        <material>
          <ambient>0.1 0.5 0.2 1</ambient>
          <diffuse>0.1 0.4 0.2 1</diffuse>
          <specular>0.2 0.4 0.1 1</specular>
          <emissive>0 0 0 1</emissive>
        </material>
      </visual>
      <visual name="stalk">
        <pose>0 0 0.005 0 0 0</pose>
        <geometry>
          <cylinder>
            <radius>0.002</radius>
            <length>0.01</length>
          </cylinder>
        </geometry>
        <material>
          <ambient>0.4 0.2 0.1 1</ambient>
          <diffuse>0.4 0.2 0.1 1</diffuse>
          <specular>0.2 0.1 0.1 1</specular>
          <emissive>0 0 0 1</emissive>
        </material>
      </visual>
      <inertial>
        <pose>0 0 0.04 0 0 0</pose>
        <mass>0.1</mass>
        <inertia>
          <ixx>0.0005</ixx>
          <ixy>0</ixy>
          <ixz>0</ixz>
          <iyy>0.0005</iyy>
          <iyz>0</iyz>
          <izz>0.0005</izz>
        </inertia>
      </inertial>
      <collision name="collision">
        <pose>0 0 0.04 0 0 0</pose>
        <geometry>
          <sphere>
            <radius>0.03</radius>
          </sphere>
        </geometry>
      </collision>
    </link>
    <joint name="joint_aab_apple" type="universal">
      <pose relative_to="branch_aab">0.0125 0 0.04912901324336615 0 1.5707963267948966 0</pose>
      <parent>branch_aab</parent>
      <child>apple_aab</child>
      <axis>
        <xyz>0 1 0 </xyz>
        <dynamics>
          <damping>0.001</damping>
          <friction>0</friction>
          <spring_reference>0</spring_reference>
          <spring_stiffness>0.2</spring_stiffness>
        </dynamics>
        <limit>
          <effort>0</effort>
        </limit>
      </axis>
      <axis2>
        <xyz>1 0 0 </xyz>
        <dynamics>
          <damping>0.001</damping>
          <friction>0</friction>
          <spring_reference>0</spring_reference>
          <spring_stiffness>0.2</spring_stiffness>
        </dynamics>
        <limit>
          <effort>0</effort>
        </limit>
      </axis2>
    </joint>
    <link name="branch_aac">
      <pose relative_to="joint_aa_aac">0 0 0.15000000000000002 0 0 0</pose>
      <visual name="visual">
        <geometry>
          <cylinder>
            <radius>0.0125</radius>
            <length>0.30000000000000004</length>
          </cylinder>
        </geometry>
        <material>
          <ambient>0.3 0.15 0.15 1</ambient>
          <diffuse>0.3 0.15 0.15 1</diffuse>
          <specular>0.0 0.0 0.0 1</specular>
          <emissive>0 0 0 1</emissive>
        </material>
      </visual>
      <collision name="collision">
        <geometry>
          <cylinder>
            <radius>0.0125</radius>
            <length>0.18000000000000002</length>
          </cylinder>
        </geometry>
      </collision>
    </link>
    <joint name="joint_aa_aac" type="revolute">
      <pose relative_to="branch_aa">0 0 0.15000000000000002 -0.5850486985670788 -0.46421030852582945 0</pose>
      <parent>branch_aa</parent>
      <child>branch_aac</child>
      <axis>
        <xyz>1 0 0 </xyz>
        <dynamics>
          <damping>20</damping>
          <friction>0</friction>
          <spring_reference>0</spring_reference>
          <spring_stiffness>1000</spring_stiffness>
        </dynamics>
        <limit>
          <effort>0</effort>
        </limit>
      </axis>
    </joint>
    <link name="apple_aac">
      <pose relative_to="joint_aac_apple">0 0 0 0 0 0</pose>
      <visual name="apple">
        <pose>0 0 0.04 0 0 0</pose>
        <geometry>
          <sphere>
            <radius>0.03</radius>
          </sphere>
        </geometry>
        <material>
          <ambient>0.1 0.5 0.2 1</ambient>
          <diffuse>0.1 0.4 0.2 1</diffuse>
          <specular>0.2 0.4 0.1 1</specular>
          <emissive>0 0 0 1</emissive>
        </material>
      </visual>
      <visual name="stalk">
        <pose>0 0 0.005 0 0 0</pose>
        <geometry>
          <cylinder>
            <radius>0.002</radius>
            <length>0.01</length>
          </cylinder>
        </geometry>
        <material>
          <ambient>0.4 0.2 0.1 1</ambient>
          <diffuse>0.4 0.2 0.1 1</diffuse>
          <specular>0.2 0.1 0.1 1</specular>
          <emissive>0 0 0 1</emissive>
        </material>
      </visual>
      <inertial>
        <pose>0 0 0.04 0 0 0</pose>
        <mass>0.1</mass>
        <inertia>
          <ixx>0.0005</ixx>
          <ixy>0</ixy>
          <ixz>0</ixz>
          <iyy>0.0005</iyy>
          <iyz>0</iyz>
          <izz>0.0005</izz>
        </inertia>
      </inertial>
      <collision name="collision">
        <pose>0 0 0.04 0 0 0</pose>
        <geometry>
          <sphere>
            <radius>0.03</radius>
          </sphere>
        </geometry>
      </collision>
    </link>
    <joint name="joint_aac_apple" type="universal">
      <pose relative_to="branch_aac">0.0125 0 -0.05876555225018183 0 1.5707963267948966 0</pose>
      <parent>branch_aac</parent>
      <child>apple_aac</child>
      <axis>
        <xyz>0 1 0 </xyz>
        <dynamics>
          <damping>0.001</damping>
          <friction>0</friction>
          <spring_reference>0</spring_reference>
          <spring_stiffness>0.2</spring_stiffness>
        </dynamics>
        <limit>
          <effort>0</effort>
        </limit>
      </axis>
      <axis2>
        <xyz>1 0 0 </xyz>
        <dynamics>
          <damping>0.001</damping>
          <friction>0</friction>
          <spring_reference>0</spring_reference>
          <spring_stiffness>0.2</spring_stiffness>
        </dynamics>
        <limit>
          <effort>0</effort>
        </limit>
      </axis2>
    </joint>
    <link name="branch_ab">
      <pose relative_to="joint_a_ab">0 0 0.1875 0 0 0</pose>
      <visual name="visual">
        <geometry>
          <cylinder>
            <radius>0.016666666666666666</radius>
            <length>0.375</length>
          </cylinder>
        </geometry>
        <material>
          <ambient>0.3 0.15 0.15 1</ambient>
          <diffuse>0.3 0.15 0.15 1</diffuse>
          <specular>0.0 0.0 0.0 1</specular>
          <emissive>0 0 0 1</emissive>
        </material>
      </visual>
      <collision name="collision">
        <geometry>
          <cylinder>
            <radius>0.016666666666666666</radius>
            <length>0.22499999999999998</length>
          </cylinder>
        </geometry>
      </collision>
    </link>
    <joint name="joint_a_ab" type="revolute">
      <pose relative_to="branch_a">0 0 0.1875 0.07993928222184987 -0.5343177552674038 0</pose>
      <parent>branch_a</parent>
      <child>branch_ab</child>
      <axis>
        <xyz>1 0 0 </xyz>
        <dynamics>
          <damping>100</damping>
          <friction>0</friction>
          <spring_reference>0</spring_reference>
          <spring_stiffness>5000</spring_stiffness>
        </dynamics>
        <limit>
          <effort>0</effort>
        </limit>
      </axis>
    </joint>
    <link name="apple_ab">
      <pose relative_to="joint_ab_apple">0 0 0 0 0 0</pose>
      <visual name="apple">
        <pose>0 0 0.04 0 0 0</pose>
        <geometry>
          <sphere>
            <radius>0.03</radius>
          </sphere>
        </geometry>
        <material>
          <ambient>0.1 0.5 0.2 1</ambient>
          <diffuse>0.1 0.4 0.2 1</diffuse>
          <specular>0.2 0.4 0.1 1</specular>
          <emissive>0 0 0 1</emissive>
        </material>
      </visual>
      <visual name="stalk">
        <pose>0 0 0.005 0 0 0</pose>
        <geometry>
          <cylinder>
            <radius>0.002</radius>
            <length>0.01</length>
          </cylinder>
        </geometry>
        <material>
          <ambient>0.4 0.2 0.1 1</ambient>
          <diffuse>0.4 0.2 0.1 1</diffuse>
          <specular>0.2 0.1 0.1 1</specular>
          <emissive>0 0 0 1</emissive>
        </material>
      </visual>
      <inertial>
        <pose>0 0 0.04 0 0 0</pose>
        <mass>0.1</mass>
        <inertia>
          <ixx>0.0005</ixx>
          <ixy>0</ixy>
          <ixz>0</ixz>
          <iyy>0.0005</iyy>
          <iyz>0</iyz>
          <izz>0.0005</izz>
        </inertia>
      </inertial>
      <collision name="collision">
        <pose>0 0 0.04 0 0 0</pose>
        <geometry>
          <sphere>
            <radius>0.03</radius>
          </sphere>
        </geometry>
      </collision>
    </link>
    <joint name="joint_ab_apple" type="universal">
      <pose relative_to="branch_ab">0.016666666666666666 0 -0.06025791366978492 0 1.5707963267948966 0</pose>
      <parent>branch_ab</parent>
      <child>apple_ab</child>
      <axis>
        <xyz>0 1 0 </xyz>
        <dynamics>
          <damping>0.001</damping>
          <friction>0</friction>
          <spring_reference>0</spring_reference>
          <spring_stiffness>0.2</spring_stiffness>
        </dynamics>
        <limit>
          <effort>0</effort>
        </limit>
      </axis>
      <axis2>
        <xyz>1 0 0 </xyz>
        <dynamics>
          <damping>0.001</damping>
          <friction>0</friction>
          <spring_reference>0</spring_reference>
          <spring_stiffness>0.2</spring_stiffness>
        </dynamics>
        <limit>
          <effort>0</effort>
        </limit>
      </axis2>
    </joint>
    <link name="branch_aba">
      <pose relative_to="joint_ab_aba">0 0 0.15000000000000002 0 0 0</pose>
      <visual name="visual">
        <geometry>
          <cylinder>
            <radius>0.0125</radius>
            <length>0.30000000000000004</length>
          </cylinder>
        </geometry>
        <material>
          <ambient>0.3 0.15 0.15 1</ambient>
          <diffuse>0.3 0.15 0.15 1</diffuse>
          <specular>0.0 0.0 0.0 1</specular>
          <emissive>0 0 0 1</emissive>
        </material>
      </visual>
      <collision name="collision">
        <geometry>
          <cylinder>
            <radius>0.0125</radius>
            <length>0.18000000000000002</length>
          </cylinder>
        </geometry>
      </collision>
    </link>
    <joint name="joint_ab_aba" type="revolute">
      <pose relative_to="branch_ab">0 0 0.15000000000000002 -0.2055243971905708 -0.29899361555301746 0</pose>
      <parent>branch_ab</parent>
      <child>branch_aba</child>
      <axis>
        <xyz>1 0 0 </xyz>
        <dynamics>
          <damping>20</damping>
          <friction>0</friction>
          <spring_reference>0</spring_reference>
          <spring_stiffness>1000</spring_stiffness>
        </dynamics>
        <limit>
          <effort>0</effort>
        </limit>
      </axis>
    </joint>
    <link name="apple_aba">
      <pose relative_to="joint_aba_apple">0 0 0 0 0 0</pose>
      <visual name="apple">
        <pose>0 0 0.04 0 0 0</pose>
        <geometry>
          <sphere>
            <radius>0.03</radius>
          </sphere>
        </geometry>
        <material>
          <ambient>0.1 0.5 0.2 1</ambient>
          <diffuse>0.1 0.4 0.2 1</diffuse>
          <specular>0.2 0.4 0.1 1</specular>
          <emissive>0 0 0 1</emissive>
        </material>
      </visual>
      <visual name="stalk">
        <pose>0 0 0.005 0 0 0</pose>
        <geometry>
          <cylinder>
            <radius>0.002</radius>
            <length>0.01</length>
          </cylinder>
        </geometry>
        <material>
          <ambient>0.4 0.2 0.1 1</ambient>
          <diffuse>0.4 0.2 0.1 1</diffuse>
          <specular>0.2 0.1 0.1 1</specular>
          <emissive>0 0 0 1</emissive>
        </material>
      </visual>
      <inertial>
        <pose>0 0 0.04 0 0 0</pose>
        <mass>0.1</mass>
        <inertia>
          <ixx>0.0005</ixx>
          <ixy>0</ixy>
          <ixz>0</ixz>
          <iyy>0.0005</iyy>
          <iyz>0</iyz>
          <izz>0.0005</izz>
        </inertia>
      </inertial>
      <collision name="collision">
        <pose>0 0 0.04 0 0 0</pose>
        <geometry>
          <sphere>
            <radius>0.03</radius>
          </sphere>
        </geometry>
      </collision>
    </link>
    <joint name="joint_aba_apple" type="universal">
      <pose relative_to="branch_aba">0.0125 0 0.048653253785119886 0 1.5707963267948966 0</pose>
      <parent>branch_aba</parent>
      <child>apple_aba</child>
      <axis>
        <xyz>0 1 0 </xyz>
        <dynamics>
          <damping>0.001</damping>
          <friction>0</friction>
          <spring_reference>0</spring_reference>
          <spring_stiffness>0.2</spring_stiffness>
        </dynamics>
        <limit>
          <effort>0</effort>
        </limit>
      </axis>
      <axis2>
        <xyz>1 0 0 </xyz>
        <dynamics>
          <damping>0.001</damping>
          <friction>0</friction>
          <spring_reference>0</spring_reference>
          <spring_stiffness>0.2</spring_stiffness>
        </dynamics>
        <limit>
          <effort>0</effort>
        </limit>
      </axis2>
    </joint>
    <link name="branch_abb">
      <pose relative_to="joint_ab_abb">0 0 0.15000000000000002 0 0 0</pose>
      <visual name="visual">
        <geometry>
          <cylinder>
            <radius>0.0125</radius>
            <length>0.30000000000000004</length>
          </cylinder>
        </geometry>
        <material>
          <ambient>0.3 0.15 0.15 1</ambient>
          <diffuse>0.3 0.15 0.15 1</diffuse>
          <specular>0.0 0.0 0.0 1</specular>
          <emissive>0 0 0 1</emissive>
        </material>
      </visual>
      <collision name="collision">
        <geometry>
          <cylinder>
            <radius>0.0125</radius>
            <length>0.18000000000000002</length>
          </cylinder>
        </geometry>
      </collision>
    </link>
    <joint name="joint_ab_abb" type="revolute">
      <pose relative_to="branch_ab">0 0 0.15000000000000002 -0.4165990473611153 0.0262015320450531 0</pose>
      <parent>branch_ab</parent>
      <child>branch_abb</child>
      <axis>
        <xyz>1 0 0 </xyz>
        <dynamics>
          <damping>20</damping>
          <friction>0</friction>
          <spring_reference>0</spring_reference>
          <spring_stiffness>1000</spring_stiffness>
        </dynamics>
        <limit>
          <effort>0</effort>
        </limit>
      </axis>
    </joint>
    <link name="apple_abb">
      <pose relative_to="joint_abb_apple">0 0 0 0 0 0</pose>
      <visual name="apple">
        <pose>0 0 0.04 0 0 0</pose>
        <geometry>
          <sphere>
            <radius>0.03</radius>
          </sphere>
        </geometry>
        <material>
          <ambient>0.1 0.5 0.2 1</ambient>
          <diffuse>0.1 0.4 0.2 1</diffuse>
          <specular>0.2 0.4 0.1 1</specular>
          <emissive>0 0 0 1</emissive>
        </material>
      </visual>
      <visual name="stalk">
        <pose>0 0 0.005 0 0 0</pose>
        <geometry>
          <cylinder>
            <radius>0.002</radius>
            <length>0.01</length>
          </cylinder>
        </geometry>
        <material>
          <ambient>0.4 0.2 0.1 1</ambient>
          <diffuse>0.4 0.2 0.1 1</diffuse>
          <specular>0.2 0.1 0.1 1</specular>
          <emissive>0 0 0 1</emissive>
        </material>
      </visual>
      <inertial>
        <pose>0 0 0.04 0 0 0</pose>
        <mass>0.1</mass>
        <inertia>
          <ixx>0.0005</ixx>
          <ixy>0</ixy>
          <ixz>0</ixz>
          <iyy>0.0005</iyy>
          <iyz>0</iyz>
          <izz>0.0005</izz>
        </inertia>
      </inertial>
      <collision name="collision">
        <pose>0 0 0.04 0 0 0</pose>
        <geometry>
          <sphere>
            <radius>0.03</radius>
          </sphere>
        </geometry>
      </collision>
    </link>
    <joint name="joint_abb_apple" type="universal">
      <pose relative_to="branch_abb">0.0125 0 -0.043497671719941226 0 1.5707963267948966 0</pose>
      <parent>branch_abb</parent>
      <child>apple_abb</child>
      <axis>
        <xyz>0 1 0 </xyz>
        <dynamics>
          <damping>0.001</damping>
          <friction>0</friction>
          <spring_reference>0</spring_reference>
          <spring_stiffness>0.2</spring_stiffness>
        </dynamics>
        <limit>
          <effort>0</effort>
        </limit>
      </axis>
      <axis2>
        <xyz>1 0 0 </xyz>
        <dynamics>
          <damping>0.001</damping>
          <friction>0</friction>
          <spring_reference>0</spring_reference>
          <spring_stiffness>0.2</spring_stiffness>
        </dynamics>
        <limit>
          <effort>0</effort>
        </limit>
      </axis2>
    </joint>
    <link name="branch_abc">
      <pose relative_to="joint_ab_abc">0 0 0.15000000000000002 0 0 0</pose>
      <visual name="visual">
        <geometry>
          <cylinder>
            <radius>0.0125</radius>
            <length>0.30000000000000004</length>
          </cylinder>
        </geometry>
        <material>
          <ambient>0.3 0.15 0.15 1</ambient>
          <diffuse>0.3 0.15 0.15 1</diffuse>
          <specular>0.0 0.0 0.0 1</specular>
          <emissive>0 0 0 1</emissive>
        </material>
      </visual>
      <collision name="collision">
        <geometry>
          <cylinder>
            <radius>0.0125</radius>
            <length>0.18000000000000002</length>
          </cylinder>
        </geometry>
      </collision>
    </link>
    <joint name="joint_ab_abc" type="revolute">
      <pose relative_to="branch_ab">0 0 0.15000000000000002 -0.5899281585870833 -0.04180420315550637 0</pose>
      <parent>branch_ab</parent>
      <child>branch_abc</child>
      <axis>
        <xyz>1 0 0 </xyz>
        <dynamics>
          <damping>20</damping>
          <friction>0</friction>
          <spring_reference>0</spring_reference>
          <spring_stiffness>1000</spring_stiffness>
        </dynamics>
        <limit>
          <effort>0</effort>
        </limit>
      </axis>
    </joint>
    <link name="apple_abc">
      <pose relative_to="joint_abc_apple">0 0 0 0 0 0</pose>
      <visual name="apple">
        <pose>0 0 0.04 0 0 0</pose>
        <geometry>
          <sphere>
            <radius>0.03</radius>
          </sphere>
        </geometry>
        <material>
          <ambient>0.1 0.5 0.2 1</ambient>
          <diffuse>0.1 0.4 0.2 1</diffuse>
          <specular>0.2 0.4 0.1 1</specular>
          <emissive>0 0 0 1</emissive>
        </material>
      </visual>
      <visual name="stalk">
        <pose>0 0 0.005 0 0 0</pose>
        <geometry>
          <cylinder>
            <radius>0.002</radius>
            <length>0.01</length>
          </cylinder>
        </geometry>
        <material>
          <ambient>0.4 0.2 0.1 1</ambient>
          <diffuse>0.4 0.2 0.1 1</diffuse>
          <specular>0.2 0.1 0.1 1</specular>
          <emissive>0 0 0 1</emissive>
        </material>
      </visual>
      <inertial>
        <pose>0 0 0.04 0 0 0</pose>
        <mass>0.1</mass>
        <inertia>
          <ixx>0.0005</ixx>
          <ixy>0</ixy>
          <ixz>0</ixz>
          <iyy>0.0005</iyy>
          <iyz>0</iyz>
          <izz>0.0005</izz>
        </inertia>
      </inertial>
      <collision name="collision">
        <pose>0 0 0.04 0 0 0</pose>
        <geometry>
          <sphere>
            <radius>0.03</radius>
          </sphere>
        </geometry>
      </collision>
    </link>
    <joint name="joint_abc_apple" type="universal">
      <pose relative_to="branch_abc">0.0125 0 0.0414589656884858 0 1.5707963267948966 0</pose>
      <parent>branch_abc</parent>
      <child>apple_abc</child>
      <axis>
        <xyz>0 1 0 </xyz>
        <dynamics>
          <damping>0.001</damping>
          <friction>0</friction>
          <spring_reference>0</spring_reference>
          <spring_stiffness>0.2</spring_stiffness>
        </dynamics>
        <limit>
          <effort>0</effort>
        </limit>
      </axis>
      <axis2>
        <xyz>1 0 0 </xyz>
        <dynamics>
          <damping>0.001</damping>
          <friction>0</friction>
          <spring_reference>0</spring_reference>
          <spring_stiffness>0.2</spring_stiffness>
        </dynamics>
        <limit>
          <effort>0</effort>
        </limit>
      </axis2>
    </joint>
    <link name="branch_ac">
      <pose relative_to="joint_a_ac">0 0 0.1875 0 0 0</pose>
      <visual name="visual">
        <geometry>
          <cylinder>
            <radius>0.016666666666666666</radius>
            <length>0.375</length>
          </cylinder>
        </geometry>
        <material>
          <ambient>0.3 0.15 0.15 1</ambient>
          <diffuse>0.3 0.15 0.15 1</diffuse>
          <specular>0.0 0.0 0.0 1</specular>
          <emissive>0 0 0 1</emissive>
        </material>
      </visual>
      <collision name="collision">
        <geometry>
          <cylinder>
            <radius>0.016666666666666666</radius>
            <length>0.22499999999999998</length>
          </cylinder>
        </geometry>
      </collision>
    </link>
    <joint name="joint_a_ac" type="revolute">
      <pose relative_to="branch_a">0 0 0.1875 0.003714683995236334 0.7021099538276964 0</pose>
      <parent>branch_a</parent>
      <child>branch_ac</child>
      <axis>
        <xyz>1 0 0 </xyz>
        <dynamics>
          <damping>100</damping>
          <friction>0</friction>
          <spring_reference>0</spring_reference>
          <spring_stiffness>5000</spring_stiffness>
        </dynamics>
        <limit>
          <effort>0</effort>
        </limit>
      </axis>
    </joint>
    <link name="apple_ac">
      <pose relative_to="joint_ac_apple">0 0 0 0 0 0</pose>
      <visual name="apple">
        <pose>0 0 0.04 0 0 0</pose>
        <geometry>
          <sphere>
            <radius>0.03</radius>
          </sphere>
        </geometry>
        <material>
          <ambient>0.1 0.5 0.2 1</ambient>
          <diffuse>0.1 0.4 0.2 1</diffuse>
          <specular>0.2 0.4 0.1 1</specular>
          <emissive>0 0 0 1</emissive>
        </material>
      </visual>
      <visual name="stalk">
        <pose>0 0 0.005 0 0 0</pose>
        <geometry>
          <cylinder>
            <radius>0.002</radius>
            <length>0.01</length>
          </cylinder>
        </geometry>
        <material>
          <ambient>0.4 0.2 0.1 1</ambient>
          <diffuse>0.4 0.2 0.1 1</diffuse>
          <specular>0.2 0.1 0.1 1</specular>
          <emissive>0 0 0 1</emissive>
        </material>
      </visual>
      <inertial>
        <pose>0 0 0.04 0 0 0</pose>
        <mass>0.1</mass>
        <inertia>
          <ixx>0.0005</ixx>
          <ixy>0</ixy>
          <ixz>0</ixz>
          <iyy>0.0005</iyy>
          <iyz>0</iyz>
          <izz>0.0005</izz>
        </inertia>
      </inertial>
      <collision name="collision">
        <pose>0 0 0.04 0 0 0</pose>
        <geometry>
          <sphere>
            <radius>0.03</radius>
          </sphere>
        </geometry>
      </collision>
    </link>
    <joint name="joint_ac_apple" type="universal">
      <pose relative_to="branch_ac">0.016666666666666666 0 0.03635233932655394 0 1.5707963267948966 0</pose>
      <parent>branch_ac</parent>
      <child>apple_ac</child>
      <axis>
        <xyz>0 1 0 </xyz>
        <dynamics>
          <damping>0.001</damping>
          <friction>0</friction>
          <spring_reference>0</spring_reference>
          <spring_stiffness>0.2</spring_stiffness>
        </dynamics>
        <limit>
          <effort>0</effort>
        </limit>
      </axis>
      <axis2>
        <xyz>1 0 0 </xyz>
        <dynamics>
          <damping>0.001</damping>
          <friction>0</friction>
          <spring_reference>0</spring_reference>
          <spring_stiffness>0.2</spring_stiffness>
        </dynamics>
        <limit>
          <effort>0</effort>
        </limit>
      </axis2>
    </joint>
    <link name="branch_aca">
      <pose relative_to="joint_ac_aca">0 0 0.15000000000000002 0 0 0</pose>
      <visual name="visual">
        <geometry>
          <cylinder>
            <radius>0.0125</radius>
            <length>0.30000000000000004</length>
          </cylinder>
        </geometry>
        <material>
          <ambient>0.3 0.15 0.15 1</ambient>
          <diffuse>0.3 0.15 0.15 1</diffuse>
          <specular>0.0 0.0 0.0 1</specular>
          <emissive>0 0 0 1</emissive>
        </material>
      </visual>
      <collision name="collision">
        <geometry>
          <cylinder>
            <radius>0.0125</radius>
            <length>0.18000000000000002</length>
          </cylinder>
        </geometry>
      </collision>
    </link>
    <joint name="joint_ac_aca" type="revolute">
      <pose relative_to="branch_ac">0 0 0.15000000000000002 -0.7433000245719827 -0.06542073366739592 0</pose>
      <parent>branch_ac</parent>
      <child>branch_aca</child>
      <axis>
        <xyz>1 0 0 </xyz>
        <dynamics>
          <damping>20</damping>
          <friction>0</friction>
          <spring_reference>0</spring_reference>
          <spring_stiffness>1000</spring_stiffness>
        </dynamics>
        <limit>
          <effort>0</effort>
        </limit>
      </axis>
    </joint>
    <link name="apple_aca">
      <pose relative_to="joint_aca_apple">0 0 0 0 0 0</pose>
      <visual name="apple">
        <pose>0 0 0.04 0 0 0</pose>
        <geometry>
          <sphere>
            <radius>0.03</radius>
          </sphere>
        </geometry>
        <material>
          <ambient>0.1 0.5 0.2 1</ambient>
          <diffuse>0.1 0.4 0.2 1</diffuse>
          <specular>0.2 0.4 0.1 1</specular>
          <emissive>0 0 0 1</emissive>
        </material>
      </visual>
      <visual name="stalk">
        <pose>0 0 0.005 0 0 0</pose>
        <geometry>
          <cylinder>
            <radius>0.002</radius>
            <length>0.01</length>
          </cylinder>
        </geometry>
        <material>
          <ambient>0.4 0.2 0.1 1</ambient>
          <diffuse>0.4 0.2 0.1 1</diffuse>
          <specular>0.2 0.1 0.1 1</specular>
          <emissive>0 0 0 1</emissive>
        </material>
      </visual>
      <inertial>
        <pose>0 0 0.04 0 0 0</pose>
        <mass>0.1</mass>
        <inertia>
          <ixx>0.0005</ixx>
          <ixy>0</ixy>
          <ixz>0</ixz>
          <iyy>0.0005</iyy>
          <iyz>0</iyz>
          <izz>0.0005</izz>
        </inertia>
      </inertial>
      <collision name="collision">
        <pose>0 0 0.04 0 0 0</pose>
        <geometry>
          <sphere>
            <radius>0.03</radius>
          </sphere>
        </geometry>
      </collision>
    </link>
    <joint name="joint_aca_apple" type="universal">
      <pose relative_to="branch_aca">0.0125 0 0.028874015664511286 0 1.5707963267948966 0</pose>
      <parent>branch_aca</parent>
      <child>apple_aca</child>
      <axis>
        <xyz>0 1 0 </xyz>
        <dynamics>
          <damping>0.001</damping>
          <friction>0</friction>
          <spring_reference>0</spring_reference>
          <spring_stiffness>0.2</spring_stiffness>
        </dynamics>
        <limit>
          <effort>0</effort>
        </limit>
      </axis>
      <axis2>
        <xyz>1 0 0 </xyz>
        <dynamics>
          <damping>0.001</damping>
          <friction>0</friction>
          <spring_reference>0</spring_reference>
          <spring_stiffness>0.2</spring_stiffness>
        </dynamics>
        <limit>
          <effort>0</effort>
        </limit>
      </axis2>
    </joint>
    <link name="branch_acb">
      <pose relative_to="joint_ac_acb">0 0 0.15000000000000002 0 0 0</pose>
      <visual name="visual">
        <geometry>
          <cylinder>
            <radius>0.0125</radius>
            <length>0.30000000000000004</length>
          </cylinder>
        </geometry>
        <material>
          <ambient>0.3 0.15 0.15 1</ambient>
          <diffuse>0.3 0.15 0.15 1</diffuse>
          <specular>0.0 0.0 0.0 1</specular>
          <emissive>0 0 0 1</emissive>
        </material>
      </visual>
      <collision name="collision">
        <geometry>
          <cylinder>
            <radius>0.0125</radius>
            <length>0.18000000000000002</length>
          </cylinder>
        </geometry>
      </collision>
    </link>
    <joint name="joint_ac_acb" type="revolute">
      <pose relative_to="branch_ac">0 0 0.15000000000000002 0.543801241729599 0.358486870408058 0</pose>
      <parent>branch_ac</parent>
      <child>branch_acb</child>
      <axis>
        <xyz>1 0 0 </xyz>
        <dynamics>
          <damping>20</damping>
          <friction>0</friction>
          <spring_reference>0</spring_reference>
          <spring_stiffness>1000</spring_stiffness>
        </dynamics>
        <limit>
          <effort>0</effort>
        </limit>
      </axis>
    </joint>
    <link name="apple_acb">
      <pose relative_to="joint_acb_apple">0 0 0 0 0 0</pose>
      <visual name="apple">
        <pose>0 0 0.04 0 0 0</pose>
        <geometry>
          <sphere>
            <radius>0.03</radius>
          </sphere>
        </geometry>
        <material>
          <ambient>0.1 0.5 0.2 1</ambient>
          <diffuse>0.1 0.4 0.2 1</diffuse>
          <specular>0.2 0.4 0.1 1</specular>
          <emissive>0 0 0 1</emissive>
        </material>
      </visual>
      <visual name="stalk">
        <pose>0 0 0.005 0 0 0</pose>
        <geometry>
          <cylinder>
            <radius>0.002</radius>
            <length>0.01</length>
          </cylinder>
        </geometry>
        <material>
          <ambient>0.4 0.2 0.1 1</ambient>
          <diffuse>0.4 0.2 0.1 1</diffuse>
          <specular>0.2 0.1 0.1 1</specular>
          <emissive>0 0 0 1</emissive>
        </material>
      </visual>
      <inertial>
        <pose>0 0 0.04 0 0 0</pose>
        <mass>0.1</mass>
        <inertia>
          <ixx>0.0005</ixx>
          <ixy>0</ixy>
          <ixz>0</ixz>
          <iyy>0.0005</iyy>
          <iyz>0</iyz>
          <izz>0.0005</izz>
        </inertia>
      </inertial>
      <collision name="collision">
        <pose>0 0 0.04 0 0 0</pose>
        <geometry>
          <sphere>
            <radius>0.03</radius>
          </sphere>
        </geometry>
      </collision>
    </link>
    <joint name="joint_acb_apple" type="universal">
      <pose relative_to="branch_acb">0.0125 0 0.04205129181644094 0 1.5707963267948966 0</pose>
      <parent>branch_acb</parent>
      <child>apple_acb</child>
      <axis>
        <xyz>0 1 0 </xyz>
        <dynamics>
          <damping>0.001</damping>
          <friction>0</friction>
          <spring_reference>0</spring_reference>
          <spring_stiffness>0.2</spring_stiffness>
        </dynamics>
        <limit>
          <effort>0</effort>
        </limit>
      </axis>
      <axis2>
        <xyz>1 0 0 </xyz>
        <dynamics>
          <damping>0.001</damping>
          <friction>0</friction>
          <spring_reference>0</spring_reference>
          <spring_stiffness>0.2</spring_stiffness>
        </dynamics>
        <limit>
          <effort>0</effort>
        </limit>
      </axis2>
    </joint>
    <link name="branch_acc">
      <pose relative_to="joint_ac_acc">0 0 0.15000000000000002 0 0 0</pose>
      <visual name="visual">
        <geometry>
          <cylinder>
            <radius>0.0125</radius>
            <length>0.30000000000000004</length>
          </cylinder>
        </geometry>
        <material>
          <ambient>0.3 0.15 0.15 1</ambient>
          <diffuse>0.3 0.15 0.15 1</diffuse>
          <specular>0.0 0.0 0.0 1</specular>
          <emissive>0 0 0 1</emissive>
        </material>
      </visual>
      <collision name="collision">
        <geometry>
          <cylinder>
            <radius>0.0125</radius>
            <length>0.18000000000000002</length>
          </cylinder>
        </geometry>
      </collision>
    </link>
    <joint name="joint_ac_acc" type="revolute">
      <pose relative_to="branch_ac">0 0 0.15000000000000002 -0.07355433197496147 -0.7262394140120589 0</pose>
      <parent>branch_ac</parent>
      <child>branch_acc</child>
      <axis>
        <xyz>1 0 0 </xyz>
        <dynamics>
          <damping>20</damping>
          <friction>0</friction>
          <spring_reference>0</spring_reference>
          <spring_stiffness>1000</spring_stiffness>
        </dynamics>
        <limit>
          <effort>0</effort>
        </limit>
      </axis>
    </joint>
    <link name="apple_acc">
      <pose relative_to="joint_acc_apple">0 0 0 0 0 0</pose>
      <visual name="apple">
        <pose>0 0 0.04 0 0 0</pose>
        <geometry>
          <sphere>
            <radius>0.03</radius>
          </sphere>
        </geometry>
        <material>
          <ambient>0.1 0.5 0.2 1</ambient>
          <diffuse>0.1 0.4 0.2 1</diffuse>
          <specular>0.2 0.4 0.1 1</specular>
          <emissive>0 0 0 1</emissive>
        </material>
      </visual>
      <visual name="stalk">
        <pose>0 0 0.005 0 0 0</pose>
        <geometry>
          <cylinder>
            <radius>0.002</radius>
            <length>0.01</length>
          </cylinder>
        </geometry>
        <material>
          <ambient>0.4 0.2 0.1 1</ambient>
          <diffuse>0.4 0.2 0.1 1</diffuse>
          <specular>0.2 0.1 0.1 1</specular>
          <emissive>0 0 0 1</emissive>
        </material>
      </visual>
      <inertial>
        <pose>0 0 0.04 0 0 0</pose>
        <mass>0.1</mass>
        <inertia>
          <ixx>0.0005</ixx>
          <ixy>0</ixy>
          <ixz>0</ixz>
          <iyy>0.0005</iyy>
          <iyz>0</iyz>
          <izz>0.0005</izz>
        </inertia>
      </inertial>
      <collision name="collision">
        <pose>0 0 0.04 0 0 0</pose>
        <geometry>
          <sphere>
            <radius>0.03</radius>
          </sphere>
        </geometry>
      </collision>
    </link>
    <joint name="joint_acc_apple" type="universal">
      <pose relative_to="branch_acc">0.0125 0 -0.046353777554053614 0 1.5707963267948966 0</pose>
      <parent>branch_acc</parent>
      <child>apple_acc</child>
      <axis>
        <xyz>0 1 0 </xyz>
        <dynamics>
          <damping>0.001</damping>
          <friction>0</friction>
          <spring_reference>0</spring_reference>
          <spring_stiffness>0.2</spring_stiffness>
        </dynamics>
        <limit>
          <effort>0</effort>
        </limit>
      </axis>
      <axis2>
        <xyz>1 0 0 </xyz>
        <dynamics>
          <damping>0.001</damping>
          <friction>0</friction>
          <spring_reference>0</spring_reference>
          <spring_stiffness>0.2</spring_stiffness>
        </dynamics>
        <limit>
          <effort>0</effort>
        </limit>
      </axis2>
    </joint>
  </model>
</sdf>