<sdf version="1.7">
  <model name="tree">
    <link name="branch_a">
      <visual name="visual">
        <geometry>
          <cylinder>
            <radius>0.06</radius>
            <length>1</length>
          </cylinder>
        </geometry>
        <material>
          <ambient>0.3 0.15 0.15 1</ambient>
          <diffuse>0.3 0.15 0.15 1</diffuse>
          <specular>0.0 0.0 0.0 1</specular>
          <emissive>0 0 0 1</emissive>
        </material>
      </visual>
      <collision name="collision">
        <geometry>
          <cylinder>
            <radius>0.06</radius>
            <length>1</length>
          </cylinder>
        </geometry>
      </collision>
    </link>
    <link name="branch_aa">
      <pose relative_to="joint_a_aa">0 0 0.1875 0 0 0</pose>
      <visual name="visual">
        <geometry>
          <cylinder>
            <radius>0.016666666666666666</radius>
            <length>0.375</length>
          </cylinder>
        </geometry>
        <material>
          <ambient>0.3 0.15 0.15 1</ambient>
          <diffuse>0.3 0.15 0.15 1</diffuse>
          <specular>0.0 0.0 0.0 1</specular>
          <emissive>0 0 0 1</emissive>
        </material>
      </visual>
      <collision name="collision">
        <geometry>
          <cylinder>
            <radius>0.016666666666666666</radius>
            <length>0.22499999999999998</length>
          </cylinder>
        </geometry>
      </collision>
    </link>
    <joint name="joint_a_aa" type="revolute">
      <pose relative_to="branch_a">0 0 0.1875 -0.19360333494148163 0.3565278796174264 0</pose>
      <parent>branch_a</parent>
      <child>branch_aa</child>
      <axis>
        <xyz>1 0 0 </xyz>
        <dynamics>
          <damping>100</damping>
          <friction>0</friction>
          <spring_reference>0</spring_reference>
          <spring_stiffness>5000</spring_stiffness>
        </dynamics>
        <limit>
          <effort>0</effort>
        </limit>
      </axis>
    </joint>
    <link name="apple_aa">
      <pose relative_to="joint_aa_apple">0 0 0 0 0 0</pose>
      <visual name="apple">
        <pose>0 0 0.04 0 0 0</pose>
        <geometry>
          <sphere>
            <radius>0.03</radius>
          </sphere>
        </geometry>
        <material>
          <ambient>0.1 0.5 0.2 1</ambient>
          <diffuse>0.1 0.4 0.2 1</diffuse>
          <specular>0.2 0.4 0.1 1</specular>
          <emissive>0 0 0 1</emissive>
        </material>
      </visual>
      <visual name="stalk">
        <pose>0 0 0.005 0 0 0</pose>
        <geometry>
          <cylinder>
            <radius>0.002</radius>
            <length>0.01</length>
          </cylinder>
        </geometry>
        <material>
          <ambient>0.4 0.2 0.1 1</ambient>
          <diffuse>0.4 0.2 0.1 1</diffuse>
          <specular>0.2 0.1 0.1 1</specular>
          <emissive>0 0 0 1</emissive>
        </material>
      </visual>
      <inertial>
        <pose>0 0 0.04 0 0 0</pose>
        <mass>0.1</mass>
        <inertia>
          <ixx>0.0005</ixx>
          <ixy>0</ixy>
          <ixz>0</ixz>
          <iyy>0.0005</iyy>
          <iyz>0</iyz>
          <izz>0.0005</izz>
        </inertia>
      </inertial>
      <collision name="collision">
        <pose>0 0 0.04 0 0 0</pose>
        <geometry>
          <sphere>
            <radius>0.03</radius>
          </sphere>
        </geometry>
      </collision>
    </link>
    <joint name="joint_aa_apple" type="universal">
      <pose relative_to="branch_aa">0.016666666666666666 0 0.009523201569111968 0 1.5707963267948966 0</pose>
      <parent>branch_aa</parent>
      <child>apple_aa</child>
      <axis>
        <xyz>0 1 0 </xyz>
        <dynamics>
          <damping>0.001</damping>
          <friction>0</friction>
          <spring_reference>0</spring_reference>
          <spring_stiffness>0.2</spring_stiffness>
        </dynamics>
        <limit>
          <effort>0</effort>
        </limit>
      </axis>
      <axis2>
        <xyz>1 0 0 </xyz>
        <dynamics>
          <damping>0.001</damping>
          <friction>0</friction>
          <spring_reference>0</spring_reference>
          <spring_stiffness>0.2</spring_stiffness>
        </dynamics>
        <limit>
          <effort>0</effort>
        </limit>
      </axis2>
    </joint>
    <link name="branch_aaa">
      <pose relative_to="joint_aa_aaa">0 0 0.15000000000000002 0 0 0</pose>
      <visual name="visual">
        <geometry>
          <cylinder>
            <radius>0.0125</radius>
            <length>0.30000000000000004</length>
          </cylinder>
        </geometry>
        <material>
          <ambient>0.3 0.15 0.15 1</ambient>
          <diffuse>0.3 0.15 0.15 1</diffuse>
          <specular>0.0 0.0 0.0 1</specular>
          <emissive>0 0 0 1</emissive>
        </material>
      </visual>
      <collision name="collision">
        <geometry>
          <cylinder>
            <radius>0.0125</radius>
            <length>0.18000000000000002</length>
          </cylinder>
        </geometry>
      </collision>
    </link>
    <joint name="joint_aa_aaa" type="revolute">
      <pose relative_to="branch_aa">0 0 0.15000000000000002 0.43829956043882323 0.29436467822598905 0</pose>
      <parent>branch_aa</parent>
      <child>branch_aaa</child>
      <axis>
        <xyz>1 0 0 </xyz>
        <dynamics>
          <damping>20</damping>
          <friction>0</friction>
          <spring_reference>0</spring_reference>
          <spring_stiffness>1000</spring_stiffness>
        </dynamics>
        <limit>
          <effort>0</effort>
        </limit>
      </axis>
    </joint>
    <link name="apple_aaa">
      <pose relative_to="joint_aaa_apple">0 0 0 0 0 0</pose>
      <visual name="apple">
        <pose>0 0 0.04 0 0 0</pose>
        <geometry>
          <sphere>
            <radius>0.03</radius>
          </sphere>
        </geometry>
        <material>
          <ambient>0.1 0.5 0.2 1</ambient>
          <diffuse>0.1 0.4 0.2 1</diffuse>
          <specular>0.2 0.4 0.1 1</specular>
          <emissive>0 0 0 1</emissive>
        </material>
      </visual>
      <visual name="stalk">
        <pose>0 0 0.005 0 0 0</pose>
        <geometry>
          <cylinder>
            <radius>0.002</radius>
            <length>0.01</length>
          </cylinder>
        </geometry>
        <material>
          <ambient>0.4 0.2 0.1 1</ambient>
          <diffuse>0.4 0.2 0.1 1</diffuse>
          <specular>0.2 0.1 0.1 1</specular>
          <emissive>0 0 0 1</emissive>
        </material>
      </visual>
      <inertial>
        <pose>0 0 0.04 0 0 0</pose>
        <mass>0.1</mass>
        <inertia>
          <ixx>0.0005</ixx>
          <ixy>0</ixy>
          <ixz>0</ixz>
          <iyy>0.0005</iyy>
          <iyz>0</iyz>
          <izz>0.0005</izz>
        </inertia>
      </inertial>
      <collision name="collision">
        <pose>0 0 0.04 0 0 0</pose>
        <geometry>
          <sphere>
            <radius>0.03</radius>
          </sphere>
        </geometry>
      </collision>
    </link>
    <joint name="joint_aaa_apple" type="universal">
      <pose relative_to="branch_aaa">0.0125 0 -0.008886596819973887 0 1.5707963267948966 0</pose>
      <parent>branch_aaa</parent>
      <child>apple_aaa</child>
      <axis>
        <xyz>0 1 0 </xyz>
        <dynamics>
          <damping>0.001</damping>
          <friction>0</friction>
          <spring_reference>0</spring_reference>
          <spring_stiffness>0.2</spring_stiffness>
        </dynamics>
        <limit>
          <effort>0</effort>
        </limit>
      </axis>
      <axis2>
        <xyz>1 0 0 </xyz>
        <dynamics>
          <damping>0.001</damping>
          <friction>0</friction>
          <spring_reference>0</spring_reference>
          <spring_stiffness>0.2</spring_stiffness>
        </dynamics>
        <limit>
          <effort>0</effort>
        </limit>
      </axis2>
    </joint>
  </model>
</sdf>