<sdf version="1.7">
  <model name="tree">
    <link name="branch_a">
      <visual name="visual">
        <geometry>
          <cylinder>
            <radius>0.06</radius>
            <length>1</length>
          </cylinder>
        </geometry>
        <material>
          <ambient>0.3 0.15 0.15 1</ambient>
          <diffuse>0.3 0.15 0.15 1</diffuse>
          <specular>0.0 0.0 0.0 1</specular>
          <emissive>0 0 0 1</emissive>
        </material>
      </visual>
      <collision name="collision">
        <geometry>
          <cylinder>
            <radius>0.06</radius>
            <length>1</length>
          </cylinder>
        </geometry>
      </collision>
    </link>
    <link name="branch_aa">
      <pose relative_to="joint2_a_couple_aa">0 0 0.3333333333333333 0 0 0</pose>
      <visual name="visual">
        <geometry>
          <cylinder>
            <radius>0.025</radius>
            <length>0.6666666666666666</length>
          </cylinder>
        </geometry>
        <material>
          <ambient>0.3 0.15 0.15 1</ambient>
          <diffuse>0.3 0.15 0.15 1</diffuse>
          <specular>0.0 0.0 0.0 1</specular>
          <emissive>0 0 0 1</emissive>
        </material>
      </visual>
      <collision name="collision">
        <geometry>
          <cylinder>
            <radius>0.025</radius>
            <length>0.39999999999999997</length>
          </cylinder>
        </geometry>
      </collision>
    </link>
    <joint name="joint1_a_couple_aa" type="revolute">
      <pose relative_to="branch_a">0 0 0.18301479073633892 -0.6283185307179586 0.6283185307179586 0</pose>
      <parent>branch_a</parent>
      <child>couple_a_aa</child>
      <axis>
        <xyz>1 0 0 </xyz>
        <dynamics>
          <damping>100</damping>
          <friction>0</friction>
          <spring_reference>0</spring_reference>
          <spring_stiffness>2000</spring_stiffness>
        </dynamics>
        <limit>
          <effort>0</effort>
        </limit>
      </axis>
    </joint>
    <joint name="joint2_a_couple_aa" type="revolute">
      <pose relative_to="couple_a_aa">0 0 0.01 0 0 0</pose>
      <parent>couple_a_aa</parent>
      <child>branch_aa</child>
      <axis>
        <xyz>0 1 0 </xyz>
        <dynamics>
          <damping>100</damping>
          <friction>0</friction>
          <spring_reference>0</spring_reference>
          <spring_stiffness>2000</spring_stiffness>
        </dynamics>
        <limit>
          <effort>0</effort>
        </limit>
      </axis>
    </joint>
    <link name="couple_a_aa">
      <pose relative_to="joint1_a_couple_aa">0 0 0 0 0 0</pose>
    </link>
    <link name="apple_aa">
      <pose relative_to="joint_aa_apple">0 0 0 0 0 0</pose>
      <visual name="apple">
        <pose>0 0 0.04 0 0 0</pose>
        <geometry>
          <sphere>
            <radius>0.03</radius>
          </sphere>
        </geometry>
        <material>
          <ambient>0.1 0.5 0.2 1</ambient>
          <diffuse>0.1 0.4 0.2 1</diffuse>
          <specular>0.2 0.4 0.1 1</specular>
          <emissive>0 0 0 1</emissive>
        </material>
      </visual>
      <visual name="stalk">
        <pose>0 0 0.005 0 0 0</pose>
        <geometry>
          <cylinder>
            <radius>0.002</radius>
            <length>0.01</length>
          </cylinder>
        </geometry>
        <material>
          <ambient>0.4 0.2 0.1 1</ambient>
          <diffuse>0.4 0.2 0.1 1</diffuse>
          <specular>0.2 0.1 0.1 1</specular>
          <emissive>0 0 0 1</emissive>
        </material>
      </visual>
      <inertial>
        <pose>0 0 0.04 0 0 0</pose>
        <mass>0.1</mass>
        <inertia>
          <ixx>0.0005</ixx>
          <ixy>0</ixy>
          <ixz>0</ixz>
          <iyy>0.0005</iyy>
          <iyz>0</iyz>
          <izz>0.0005</izz>
        </inertia>
      </inertial>
      <collision name="collision">
        <pose>0 0 0.04 0 0 0</pose>
        <geometry>
          <sphere>
            <radius>0.03</radius>
          </sphere>
        </geometry>
      </collision>
    </link>
    <joint name="joint_aa_apple" type="universal">
      <pose relative_to="branch_aa">0.025 0 0.212748841202469 0 1.5707963267948966 0</pose>
      <parent>branch_aa</parent>
      <child>apple_aa</child>
      <axis>
        <xyz>0 1 0 </xyz>
        <dynamics>
          <damping>0.001</damping>
          <friction>0</friction>
          <spring_reference>0</spring_reference>
          <spring_stiffness>0.2</spring_stiffness>
        </dynamics>
        <limit>
          <effort>0</effort>
        </limit>
      </axis>
      <axis2>
        <xyz>1 0 0 </xyz>
        <dynamics>
          <damping>0.001</damping>
          <friction>0</friction>
          <spring_reference>0</spring_reference>
          <spring_stiffness>0.2</spring_stiffness>
        </dynamics>
        <limit>
          <effort>0</effort>
        </limit>
      </axis2>
    </joint>
    <link name="branch_aaa">
      <pose relative_to="joint2_aa_couple_aaa">0 0 0.25 0 0 0</pose>
      <visual name="visual">
        <geometry>
          <cylinder>
            <radius>0.016666666666666666</radius>
            <length>0.5</length>
          </cylinder>
        </geometry>
        <material>
          <ambient>0.3 0.15 0.15 1</ambient>
          <diffuse>0.3 0.15 0.15 1</diffuse>
          <specular>0.0 0.0 0.0 1</specular>
          <emissive>0 0 0 1</emissive>
        </material>
      </visual>
      <collision name="collision">
        <geometry>
          <cylinder>
            <radius>0.016666666666666666</radius>
            <length>0.3</length>
          </cylinder>
        </geometry>
      </collision>
    </link>
    <joint name="joint1_aa_couple_aaa" type="revolute">
      <pose relative_to="branch_aa">0 0 0.16433340811892602 -0.4899838116195375 0.10801555146457278 0</pose>
      <parent>branch_aa</parent>
      <child>couple_aa_aaa</child>
      <axis>
        <xyz>1 0 0 </xyz>
        <dynamics>
          <damping>5</damping>
          <friction>0</friction>
          <spring_reference>0</spring_reference>
          <spring_stiffness>300</spring_stiffness>
        </dynamics>
        <limit>
          <effort>0</effort>
        </limit>
      </axis>
    </joint>
    <joint name="joint2_aa_couple_aaa" type="revolute">
      <pose relative_to="couple_aa_aaa">0 0 0.01 0 0 0</pose>
      <parent>couple_aa_aaa</parent>
      <child>branch_aaa</child>
      <axis>
        <xyz>0 1 0 </xyz>
        <dynamics>
          <damping>5</damping>
          <friction>0</friction>
          <spring_reference>0</spring_reference>
          <spring_stiffness>300</spring_stiffness>
        </dynamics>
        <limit>
          <effort>0</effort>
        </limit>
      </axis>
    </joint>
    <link name="couple_aa_aaa">
      <pose relative_to="joint1_aa_couple_aaa">0 0 0 0 0 0</pose>
    </link>
    <link name="apple_aaa">
      <pose relative_to="joint_aaa_apple">0 0 0 0 0 0</pose>
      <visual name="apple">
        <pose>0 0 0.04 0 0 0</pose>
        <geometry>
          <sphere>
            <radius>0.03</radius>
          </sphere>
        </geometry>
        <material>
          <ambient>0.1 0.5 0.2 1</ambient>
          <diffuse>0.1 0.4 0.2 1</diffuse>
          <specular>0.2 0.4 0.1 1</specular>
          <emissive>0 0 0 1</emissive>
        </material>
      </visual>
      <visual name="stalk">
        <pose>0 0 0.005 0 0 0</pose>
        <geometry>
          <cylinder>
            <radius>0.002</radius>
            <length>0.01</length>
          </cylinder>
        </geometry>
        <material>
          <ambient>0.4 0.2 0.1 1</ambient>
          <diffuse>0.4 0.2 0.1 1</diffuse>
          <specular>0.2 0.1 0.1 1</specular>
          <emissive>0 0 0 1</emissive>
        </material>
      </visual>
      <inertial>
        <pose>0 0 0.04 0 0 0</pose>
        <mass>0.1</mass>
        <inertia>
          <ixx>0.0005</ixx>
          <ixy>0</ixy>
          <ixz>0</ixz>
          <iyy>0.0005</iyy>
          <iyz>0</iyz>
          <izz>0.0005</izz>
        </inertia>
      </inertial>
      <collision name="collision">
        <pose>0 0 0.04 0 0 0</pose>
        <geometry>
          <sphere>
            <radius>0.03</radius>
          </sphere>
        </geometry>
      </collision>
    </link>
    <joint name="joint_aaa_apple" type="universal">
      <pose relative_to="branch_aaa">0.016666666666666666 0 0.12254281269703801 0 1.5707963267948966 0</pose>
      <parent>branch_aaa</parent>
      <child>apple_aaa</child>
      <axis>
        <xyz>0 1 0 </xyz>
        <dynamics>
          <damping>0.001</damping>
          <friction>0</friction>
          <spring_reference>0</spring_reference>
          <spring_stiffness>0.2</spring_stiffness>
        </dynamics>
        <limit>
          <effort>0</effort>
        </limit>
      </axis>
      <axis2>
        <xyz>1 0 0 </xyz>
        <dynamics>
          <damping>0.001</damping>
          <friction>0</friction>
          <spring_reference>0</spring_reference>
          <spring_stiffness>0.2</spring_stiffness>
        </dynamics>
        <limit>
          <effort>0</effort>
        </limit>
      </axis2>
    </joint>
    <link name="branch_aaaa">
      <pose relative_to="joint2_aaa_couple_aaaa">0 0 0.2 0 0 0</pose>
      <visual name="visual">
        <geometry>
          <cylinder>
            <radius>0.0125</radius>
            <length>0.4</length>
          </cylinder>
        </geometry>
        <material>
          <ambient>0.3 0.15 0.15 1</ambient>
          <diffuse>0.3 0.15 0.15 1</diffuse>
          <specular>0.0 0.0 0.0 1</specular>
          <emissive>0 0 0 1</emissive>
        </material>
      </visual>
      <collision name="collision">
        <geometry>
          <cylinder>
            <radius>0.0125</radius>
            <length>0.3</length>
          </cylinder>
        </geometry>
      </collision>
    </link>
    <joint name="joint1_aaa_couple_aaaa" type="revolute">
      <pose relative_to="branch_aaa">0 0 0.13521068283479198 0.419500359050168 0.3504337913076952 0</pose>
      <parent>branch_aaa</parent>
      <child>couple_aaa_aaaa</child>
      <axis>
        <xyz>1 0 0 </xyz>
        <dynamics>
          <damping>3</damping>
          <friction>0</friction>
          <spring_reference>0</spring_reference>
          <spring_stiffness>10</spring_stiffness>
        </dynamics>
        <limit>
          <effort>0</effort>
        </limit>
      </axis>
    </joint>
    <joint name="joint2_aaa_couple_aaaa" type="revolute">
      <pose relative_to="couple_aaa_aaaa">0 0 0.01 0 0 0</pose>
      <parent>couple_aaa_aaaa</parent>
      <child>branch_aaaa</child>
      <axis>
        <xyz>0 1 0 </xyz>
        <dynamics>
          <damping>3</damping>
          <friction>0</friction>
          <spring_reference>0</spring_reference>
          <spring_stiffness>10</spring_stiffness>
        </dynamics>
        <limit>
          <effort>0</effort>
        </limit>
      </axis>
    </joint>
    <link name="couple_aaa_aaaa">
      <pose relative_to="joint1_aaa_couple_aaaa">0 0 0 0 0 0</pose>
    </link>
    <link name="apple_aaaa">
      <pose relative_to="joint_aaaa_apple">0 0 0 0 0 0</pose>
      <visual name="apple">
        <pose>0 0 0.04 0 0 0</pose>
        <geometry>
          <sphere>
            <radius>0.03</radius>
          </sphere>
        </geometry>
        <material>
          <ambient>0.1 0.5 0.2 1</ambient>
          <diffuse>0.1 0.4 0.2 1</diffuse>
          <specular>0.2 0.4 0.1 1</specular>
          <emissive>0 0 0 1</emissive>
        </material>
      </visual>
      <visual name="stalk">
        <pose>0 0 0.005 0 0 0</pose>
        <geometry>
          <cylinder>
            <radius>0.002</radius>
            <length>0.01</length>
          </cylinder>
        </geometry>
        <material>
          <ambient>0.4 0.2 0.1 1</ambient>
          <diffuse>0.4 0.2 0.1 1</diffuse>
          <specular>0.2 0.1 0.1 1</specular>
          <emissive>0 0 0 1</emissive>
        </material>
      </visual>
      <inertial>
        <pose>0 0 0.04 0 0 0</pose>
        <mass>0.1</mass>
        <inertia>
          <ixx>0.0005</ixx>
          <ixy>0</ixy>
          <ixz>0</ixz>
          <iyy>0.0005</iyy>
          <iyz>0</iyz>
          <izz>0.0005</izz>
        </inertia>
      </inertial>
      <collision name="collision">
        <pose>0 0 0.04 0 0 0</pose>
        <geometry>
          <sphere>
            <radius>0.03</radius>
          </sphere>
        </geometry>
      </collision>
    </link>
    <joint name="joint_aaaa_apple" type="universal">
      <pose relative_to="branch_aaaa">0.0125 0 0.036016398252860835 0 1.5707963267948966 0</pose>
      <parent>branch_aaaa</parent>
      <child>apple_aaaa</child>
      <axis>
        <xyz>0 1 0 </xyz>
        <dynamics>
          <damping>0.001</damping>
          <friction>0</friction>
          <spring_reference>0</spring_reference>
          <spring_stiffness>0.2</spring_stiffness>
        </dynamics>
        <limit>
          <effort>0</effort>
        </limit>
      </axis>
      <axis2>
        <xyz>1 0 0 </xyz>
        <dynamics>
          <damping>0.001</damping>
          <friction>0</friction>
          <spring_reference>0</spring_reference>
          <spring_stiffness>0.2</spring_stiffness>
        </dynamics>
        <limit>
          <effort>0</effort>
        </limit>
      </axis2>
    </joint>
    <link name="branch_aaab">
      <pose relative_to="joint2_aaa_couple_aaab">0 0 0.2 0 0 0</pose>
      <visual name="visual">
        <geometry>
          <cylinder>
            <radius>0.0125</radius>
            <length>0.4</length>
          </cylinder>
        </geometry>
        <material>
          <ambient>0.3 0.15 0.15 1</ambient>
          <diffuse>0.3 0.15 0.15 1</diffuse>
          <specular>0.0 0.0 0.0 1</specular>
          <emissive>0 0 0 1</emissive>
        </material>
      </visual>
      <collision name="collision">
        <geometry>
          <cylinder>
            <radius>0.0125</radius>
            <length>0.2</length>
          </cylinder>
        </geometry>
      </collision>
    </link>
    <joint name="joint1_aaa_couple_aaab" type="revolute">
      <pose relative_to="branch_aaa">0 0 0.16816484967076595 0.7821854667239717 -0.4399609793928951 0</pose>
      <parent>branch_aaa</parent>
      <child>couple_aaa_aaab</child>
      <axis>
        <xyz>1 0 0 </xyz>
        <dynamics>
          <damping>3</damping>
          <friction>0</friction>
          <spring_reference>0</spring_reference>
          <spring_stiffness>10</spring_stiffness>
        </dynamics>
        <limit>
          <effort>0</effort>
        </limit>
      </axis>
    </joint>
    <joint name="joint2_aaa_couple_aaab" type="revolute">
      <pose relative_to="couple_aaa_aaab">0 0 0.01 0 0 0</pose>
      <parent>couple_aaa_aaab</parent>
      <child>branch_aaab</child>
      <axis>
        <xyz>0 1 0 </xyz>
        <dynamics>
          <damping>3</damping>
          <friction>0</friction>
          <spring_reference>0</spring_reference>
          <spring_stiffness>10</spring_stiffness>
        </dynamics>
        <limit>
          <effort>0</effort>
        </limit>
      </axis>
    </joint>
    <link name="couple_aaa_aaab">
      <pose relative_to="joint1_aaa_couple_aaab">0 0 0 0 0 0</pose>
    </link>
    <link name="apple_aaab">
      <pose relative_to="joint_aaab_apple">0 0 0 0 0 0</pose>
      <visual name="apple">
        <pose>0 0 0.04 0 0 0</pose>
        <geometry>
          <sphere>
            <radius>0.03</radius>
          </sphere>
        </geometry>
        <material>
          <ambient>0.1 0.5 0.2 1</ambient>
          <diffuse>0.1 0.4 0.2 1</diffuse>
          <specular>0.2 0.4 0.1 1</specular>
          <emissive>0 0 0 1</emissive>
        </material>
      </visual>
      <visual name="stalk">
        <pose>0 0 0.005 0 0 0</pose>
        <geometry>
          <cylinder>
            <radius>0.002</radius>
            <length>0.01</length>
          </cylinder>
        </geometry>
        <material>
          <ambient>0.4 0.2 0.1 1</ambient>
          <diffuse>0.4 0.2 0.1 1</diffuse>
          <specular>0.2 0.1 0.1 1</specular>
          <emissive>0 0 0 1</emissive>
        </material>
      </visual>
      <inertial>
        <pose>0 0 0.04 0 0 0</pose>
        <mass>0.1</mass>
        <inertia>
          <ixx>0.0005</ixx>
          <ixy>0</ixy>
          <ixz>0</ixz>
          <iyy>0.0005</iyy>
          <iyz>0</iyz>
          <izz>0.0005</izz>
        </inertia>
      </inertial>
      <collision name="collision">
        <pose>0 0 0.04 0 0 0</pose>
        <geometry>
          <sphere>
            <radius>0.03</radius>
          </sphere>
        </geometry>
      </collision>
    </link>
    <joint name="joint_aaab_apple" type="universal">
      <pose relative_to="branch_aaab">0.0125 0 0.16690747382412058 0 1.5707963267948966 0</pose>
      <parent>branch_aaab</parent>
      <child>apple_aaab</child>
      <axis>
        <xyz>0 1 0 </xyz>
        <dynamics>
          <damping>0.001</damping>
          <friction>0</friction>
          <spring_reference>0</spring_reference>
          <spring_stiffness>0.2</spring_stiffness>
        </dynamics>
        <limit>
          <effort>0</effort>
        </limit>
      </axis>
      <axis2>
        <xyz>1 0 0 </xyz>
        <dynamics>
          <damping>0.001</damping>
          <friction>0</friction>
          <spring_reference>0</spring_reference>
          <spring_stiffness>0.2</spring_stiffness>
        </dynamics>
        <limit>
          <effort>0</effort>
        </limit>
      </axis2>
    </joint>
    <link name="branch_aaac">
      <pose relative_to="joint2_aaa_couple_aaac">0 0 0.2 0 0 0</pose>
      <visual name="visual">
        <geometry>
          <cylinder>
            <radius>0.0125</radius>
            <length>0.4</length>
          </cylinder>
        </geometry>
        <material>
          <ambient>0.3 0.15 0.15 1</ambient>
          <diffuse>0.3 0.15 0.15 1</diffuse>
          <specular>0.0 0.0 0.0 1</specular>
          <emissive>0 0 0 1</emissive>
        </material>
      </visual>
      <collision name="collision">
        <geometry>
          <cylinder>
            <radius>0.0125</radius>
            <length>0.3</length>
          </cylinder>
        </geometry>
      </collision>
    </link>
    <joint name="joint1_aaa_couple_aaac" type="revolute">
      <pose relative_to="branch_aaa">0 0 0.17249040111407737 -0.1268807067691326 -0.1 0</pose>
      <parent>branch_aaa</parent>
      <child>couple_aaa_aaac</child>
      <axis>
        <xyz>1 0 0 </xyz>
        <dynamics>
          <damping>3</damping>
          <friction>0</friction>
          <spring_reference>0</spring_reference>
          <spring_stiffness>10</spring_stiffness>
        </dynamics>
        <limit>
          <effort>0</effort>
        </limit>
      </axis>
    </joint>
    <joint name="joint2_aaa_couple_aaac" type="revolute">
      <pose relative_to="couple_aaa_aaac">0 0 0.01 0 0 0</pose>
      <parent>couple_aaa_aaac</parent>
      <child>branch_aaac</child>
      <axis>
        <xyz>0 1 0 </xyz>
        <dynamics>
          <damping>3</damping>
          <friction>0</friction>
          <spring_reference>0</spring_reference>
          <spring_stiffness>10</spring_stiffness>
        </dynamics>
        <limit>
          <effort>0</effort>
        </limit>
      </axis>
    </joint>
    <link name="couple_aaa_aaac">
      <pose relative_to="joint1_aaa_couple_aaac">0 0 0 0 0 0</pose>
    </link>
    <link name="apple_aaac">
      <pose relative_to="joint_aaac_apple">0 0 0 0 0 0</pose>
      <visual name="apple">
        <pose>0 0 0.04 0 0 0</pose>
        <geometry>
          <sphere>
            <radius>0.03</radius>
          </sphere>
        </geometry>
        <material>
          <ambient>0.1 0.5 0.2 1</ambient>
          <diffuse>0.1 0.4 0.2 1</diffuse>
          <specular>0.2 0.4 0.1 1</specular>
          <emissive>0 0 0 1</emissive>
        </material>
      </visual>
      <visual name="stalk">
        <pose>0 0 0.005 0 0 0</pose>
        <geometry>
          <cylinder>
            <radius>0.002</radius>
            <length>0.01</length>
          </cylinder>
        </geometry>
        <material>
          <ambient>0.4 0.2 0.1 1</ambient>
          <diffuse>0.4 0.2 0.1 1</diffuse>
          <specular>0.2 0.1 0.1 1</specular>
          <emissive>0 0 0 1</emissive>
        </material>
      </visual>
      <inertial>
        <pose>0 0 0.04 0 0 0</pose>
        <mass>0.1</mass>
        <inertia>
          <ixx>0.0005</ixx>
          <ixy>0</ixy>
          <ixz>0</ixz>
          <iyy>0.0005</iyy>
          <iyz>0</iyz>
          <izz>0.0005</izz>
        </inertia>
      </inertial>
      <collision name="collision">
        <pose>0 0 0.04 0 0 0</pose>
        <geometry>
          <sphere>
            <radius>0.03</radius>
          </sphere>
        </geometry>
      </collision>
    </link>
    <joint name="joint_aaac_apple" type="universal">
      <pose relative_to="branch_aaac">0.0125 0 0.14495352435353565 0 1.5707963267948966 0</pose>
      <parent>branch_aaac</parent>
      <child>apple_aaac</child>
      <axis>
        <xyz>0 1 0 </xyz>
        <dynamics>
          <damping>0.001</damping>
          <friction>0</friction>
          <spring_reference>0</spring_reference>
          <spring_stiffness>0.2</spring_stiffness>
        </dynamics>
        <limit>
          <effort>0</effort>
        </limit>
      </axis>
      <axis2>
        <xyz>1 0 0 </xyz>
        <dynamics>
          <damping>0.001</damping>
          <friction>0</friction>
          <spring_reference>0</spring_reference>
          <spring_stiffness>0.2</spring_stiffness>
        </dynamics>
        <limit>
          <effort>0</effort>
        </limit>
      </axis2>
    </joint>
    <link name="branch_aab">
      <pose relative_to="joint2_aa_couple_aab">0 0 0.25 0 0 0</pose>
      <visual name="visual">
        <geometry>
          <cylinder>
            <radius>0.016666666666666666</radius>
            <length>0.5</length>
          </cylinder>
        </geometry>
        <material>
          <ambient>0.3 0.15 0.15 1</ambient>
          <diffuse>0.3 0.15 0.15 1</diffuse>
          <specular>0.0 0.0 0.0 1</specular>
          <emissive>0 0 0 1</emissive>
        </material>
      </visual>
      <collision name="collision">
        <geometry>
          <cylinder>
            <radius>0.016666666666666666</radius>
            <length>0.3</length>
          </cylinder>
        </geometry>
      </collision>
    </link>
    <joint name="joint1_aa_couple_aab" type="revolute">
      <pose relative_to="branch_aa">0 0 0.20304237275630543 0.16575992458130107 0.0033906171172045693 0</pose>
      <parent>branch_aa</parent>
      <child>couple_aa_aab</child>
      <axis>
        <xyz>1 0 0 </xyz>
        <dynamics>
          <damping>5</damping>
          <friction>0</friction>
          <spring_reference>0</spring_reference>
          <spring_stiffness>300</spring_stiffness>
        </dynamics>
        <limit>
          <effort>0</effort>
        </limit>
      </axis>
    </joint>
    <joint name="joint2_aa_couple_aab" type="revolute">
      <pose relative_to="couple_aa_aab">0 0 0.01 0 0 0</pose>
      <parent>couple_aa_aab</parent>
      <child>branch_aab</child>
      <axis>
        <xyz>0 1 0 </xyz>
        <dynamics>
          <damping>5</damping>
          <friction>0</friction>
          <spring_reference>0</spring_reference>
          <spring_stiffness>300</spring_stiffness>
        </dynamics>
        <limit>
          <effort>0</effort>
        </limit>
      </axis>
    </joint>
    <link name="couple_aa_aab">
      <pose relative_to="joint1_aa_couple_aab">0 0 0 0 0 0</pose>
    </link>
    <link name="apple_aab">
      <pose relative_to="joint_aab_apple">0 0 0 0 0 0</pose>
      <visual name="apple">
        <pose>0 0 0.04 0 0 0</pose>
        <geometry>
          <sphere>
            <radius>0.03</radius>
          </sphere>
        </geometry>
        <material>
          <ambient>0.1 0.5 0.2 1</ambient>
          <diffuse>0.1 0.4 0.2 1</diffuse>
          <specular>0.2 0.4 0.1 1</specular>
          <emissive>0 0 0 1</emissive>
        </material>
      </visual>
      <visual name="stalk">
        <pose>0 0 0.005 0 0 0</pose>
        <geometry>
          <cylinder>
            <radius>0.002</radius>
            <length>0.01</length>
          </cylinder>
        </geometry>
        <material>
          <ambient>0.4 0.2 0.1 1</ambient>
          <diffuse>0.4 0.2 0.1 1</diffuse>
          <specular>0.2 0.1 0.1 1</specular>
          <emissive>0 0 0 1</emissive>
        </material>
      </visual>
      <inertial>
        <pose>0 0 0.04 0 0 0</pose>
        <mass>0.1</mass>
        <inertia>
          <ixx>0.0005</ixx>
          <ixy>0</ixy>
          <ixz>0</ixz>
          <iyy>0.0005</iyy>
          <iyz>0</iyz>
          <izz>0.0005</izz>
        </inertia>
      </inertial>
      <collision name="collision">
        <pose>0 0 0.04 0 0 0</pose>
        <geometry>
          <sphere>
            <radius>0.03</radius>
          </sphere>
        </geometry>
      </collision>
    </link>
    <joint name="joint_aab_apple" type="universal">
      <pose relative_to="branch_aab">0.016666666666666666 0 0.21277964647426612 0 1.5707963267948966 0</pose>
      <parent>branch_aab</parent>
      <child>apple_aab</child>
      <axis>
        <xyz>0 1 0 </xyz>
        <dynamics>
          <damping>0.001</damping>
          <friction>0</friction>
          <spring_reference>0</spring_reference>
          <spring_stiffness>0.2</spring_stiffness>
        </dynamics>
        <limit>
          <effort>0</effort>
        </limit>
      </axis>
      <axis2>
        <xyz>1 0 0 </xyz>
        <dynamics>
          <damping>0.001</damping>
          <friction>0</friction>
          <spring_reference>0</spring_reference>
          <spring_stiffness>0.2</spring_stiffness>
        </dynamics>
        <limit>
          <effort>0</effort>
        </limit>
      </axis2>
    </joint>
    <link name="branch_aaba">
      <pose relative_to="joint2_aab_couple_aaba">0 0 0.2 0 0 0</pose>
      <visual name="visual">
        <geometry>
          <cylinder>
            <radius>0.0125</radius>
            <length>0.4</length>
          </cylinder>
        </geometry>
        <material>
          <ambient>0.3 0.15 0.15 1</ambient>
          <diffuse>0.3 0.15 0.15 1</diffuse>
          <specular>0.0 0.0 0.0 1</specular>
          <emissive>0 0 0 1</emissive>
        </material>
      </visual>
      <collision name="collision">
        <geometry>
          <cylinder>
            <radius>0.0125</radius>
            <length>0.3</length>
          </cylinder>
        </geometry>
      </collision>
    </link>
    <joint name="joint1_aab_couple_aaba" type="revolute">
      <pose relative_to="branch_aab">0 0 0.12392427473199831 0.40389501572116354 -0.7677171338531678 0</pose>
      <parent>branch_aab</parent>
      <child>couple_aab_aaba</child>
      <axis>
        <xyz>1 0 0 </xyz>
        <dynamics>
          <damping>3</damping>
          <friction>0</friction>
          <spring_reference>0</spring_reference>
          <spring_stiffness>10</spring_stiffness>
        </dynamics>
        <limit>
          <effort>0</effort>
        </limit>
      </axis>
    </joint>
    <joint name="joint2_aab_couple_aaba" type="revolute">
      <pose relative_to="couple_aab_aaba">0 0 0.01 0 0 0</pose>
      <parent>couple_aab_aaba</parent>
      <child>branch_aaba</child>
      <axis>
        <xyz>0 1 0 </xyz>
        <dynamics>
          <damping>3</damping>
          <friction>0</friction>
          <spring_reference>0</spring_reference>
          <spring_stiffness>10</spring_stiffness>
        </dynamics>
        <limit>
          <effort>0</effort>
        </limit>
      </axis>
    </joint>
    <link name="couple_aab_aaba">
      <pose relative_to="joint1_aab_couple_aaba">0 0 0 0 0 0</pose>
    </link>
    <link name="apple_aaba">
      <pose relative_to="joint_aaba_apple">0 0 0 0 0 0</pose>
      <visual name="apple">
        <pose>0 0 0.04 0 0 0</pose>
        <geometry>
          <sphere>
            <radius>0.03</radius>
          </sphere>
        </geometry>
        <material>
          <ambient>0.1 0.5 0.2 1</ambient>
          <diffuse>0.1 0.4 0.2 1</diffuse>
          <specular>0.2 0.4 0.1 1</specular>
          <emissive>0 0 0 1</emissive>
        </material>
      </visual>
      <visual name="stalk">
        <pose>0 0 0.005 0 0 0</pose>
        <geometry>
          <cylinder>
            <radius>0.002</radius>
            <length>0.01</length>
          </cylinder>
        </geometry>
        <material>
          <ambient>0.4 0.2 0.1 1</ambient>
          <diffuse>0.4 0.2 0.1 1</diffuse>
          <specular>0.2 0.1 0.1 1</specular>
          <emissive>0 0 0 1</emissive>
        </material>
      </visual>
      <inertial>
        <pose>0 0 0.04 0 0 0</pose>
        <mass>0.1</mass>
        <inertia>
          <ixx>0.0005</ixx>
          <ixy>0</ixy>
          <ixz>0</ixz>
          <iyy>0.0005</iyy>
          <iyz>0</iyz>
          <izz>0.0005</izz>
        </inertia>
      </inertial>
      <collision name="collision">
        <pose>0 0 0.04 0 0 0</pose>
        <geometry>
          <sphere>
            <radius>0.03</radius>
          </sphere>
        </geometry>
      </collision>
    </link>
    <joint name="joint_aaba_apple" type="universal">
      <pose relative_to="branch_aaba">0.0125 0 0.13622940984882048 0 1.5707963267948966 0</pose>
      <parent>branch_aaba</parent>
      <child>apple_aaba</child>
      <axis>
        <xyz>0 1 0 </xyz>
        <dynamics>
          <damping>0.001</damping>
          <friction>0</friction>
          <spring_reference>0</spring_reference>
          <spring_stiffness>0.2</spring_stiffness>
        </dynamics>
        <limit>
          <effort>0</effort>
        </limit>
      </axis>
      <axis2>
        <xyz>1 0 0 </xyz>
        <dynamics>
          <damping>0.001</damping>
          <friction>0</friction>
          <spring_reference>0</spring_reference>
          <spring_stiffness>0.2</spring_stiffness>
        </dynamics>
        <limit>
          <effort>0</effort>
        </limit>
      </axis2>
    </joint>
    <link name="branch_aabb">
      <pose relative_to="joint2_aab_couple_aabb">0 0 0.2 0 0 0</pose>
      <visual name="visual">
        <geometry>
          <cylinder>
            <radius>0.0125</radius>
            <length>0.4</length>
          </cylinder>
        </geometry>
        <material>
          <ambient>0.3 0.15 0.15 1</ambient>
          <diffuse>0.3 0.15 0.15 1</diffuse>
          <specular>0.0 0.0 0.0 1</specular>
          <emissive>0 0 0 1</emissive>
        </material>
      </visual>
      <collision name="collision">
        <geometry>
          <cylinder>
            <radius>0.0125</radius>
            <length>0.3</length>
          </cylinder>
        </geometry>
      </collision>
    </link>
    <joint name="joint1_aab_couple_aabb" type="revolute">
      <pose relative_to="branch_aab">0 0 0.13769672722772214 0.35158840398008595 0.5773464865601176 0</pose>
      <parent>branch_aab</parent>
      <child>couple_aab_aabb</child>
      <axis>
        <xyz>1 0 0 </xyz>
        <dynamics>
          <damping>3</damping>
          <friction>0</friction>
          <spring_reference>0</spring_reference>
          <spring_stiffness>10</spring_stiffness>
        </dynamics>
        <limit>
          <effort>0</effort>
        </limit>
      </axis>
    </joint>
    <joint name="joint2_aab_couple_aabb" type="revolute">
      <pose relative_to="couple_aab_aabb">0 0 0.01 0 0 0</pose>
      <parent>couple_aab_aabb</parent>
      <child>branch_aabb</child>
      <axis>
        <xyz>0 1 0 </xyz>
        <dynamics>
          <damping>3</damping>
          <friction>0</friction>
          <spring_reference>0</spring_reference>
          <spring_stiffness>10</spring_stiffness>
        </dynamics>
        <limit>
          <effort>0</effort>
        </limit>
      </axis>
    </joint>
    <link name="couple_aab_aabb">
      <pose relative_to="joint1_aab_couple_aabb">0 0 0 0 0 0</pose>
    </link>
    <link name="apple_aabb">
      <pose relative_to="joint_aabb_apple">0 0 0 0 0 0</pose>
      <visual name="apple">
        <pose>0 0 0.04 0 0 0</pose>
        <geometry>
          <sphere>
            <radius>0.03</radius>
          </sphere>
        </geometry>
        <material>
          <ambient>0.1 0.5 0.2 1</ambient>
          <diffuse>0.1 0.4 0.2 1</diffuse>
          <specular>0.2 0.4 0.1 1</specular>
          <emissive>0 0 0 1</emissive>
        </material>
      </visual>
      <visual name="stalk">
        <pose>0 0 0.005 0 0 0</pose>
        <geometry>
          <cylinder>
            <radius>0.002</radius>
            <length>0.01</length>
          </cylinder>
        </geometry>
        <material>
          <ambient>0.4 0.2 0.1 1</ambient>
          <diffuse>0.4 0.2 0.1 1</diffuse>
          <specular>0.2 0.1 0.1 1</specular>
          <emissive>0 0 0 1</emissive>
        </material>
      </visual>
      <inertial>
        <pose>0 0 0.04 0 0 0</pose>
        <mass>0.1</mass>
        <inertia>
          <ixx>0.0005</ixx>
          <ixy>0</ixy>
          <ixz>0</ixz>
          <iyy>0.0005</iyy>
          <iyz>0</iyz>
          <izz>0.0005</izz>
        </inertia>
      </inertial>
      <collision name="collision">
        <pose>0 0 0.04 0 0 0</pose>
        <geometry>
          <sphere>
            <radius>0.03</radius>
          </sphere>
        </geometry>
      </collision>
    </link>
    <joint name="joint_aabb_apple" type="universal">
      <pose relative_to="branch_aabb">0.0125 0 -0.015071427145052108 0 1.5707963267948966 0</pose>
      <parent>branch_aabb</parent>
      <child>apple_aabb</child>
      <axis>
        <xyz>0 1 0 </xyz>
        <dynamics>
          <damping>0.001</damping>
          <friction>0</friction>
          <spring_reference>0</spring_reference>
          <spring_stiffness>0.2</spring_stiffness>
        </dynamics>
        <limit>
          <effort>0</effort>
        </limit>
      </axis>
      <axis2>
        <xyz>1 0 0 </xyz>
        <dynamics>
          <damping>0.001</damping>
          <friction>0</friction>
          <spring_reference>0</spring_reference>
          <spring_stiffness>0.2</spring_stiffness>
        </dynamics>
        <limit>
          <effort>0</effort>
        </limit>
      </axis2>
    </joint>
    <link name="branch_aabc">
      <pose relative_to="joint2_aab_couple_aabc">0 0 0.2 0 0 0</pose>
      <visual name="visual">
        <geometry>
          <cylinder>
            <radius>0.0125</radius>
            <length>0.4</length>
          </cylinder>
        </geometry>
        <material>
          <ambient>0.3 0.15 0.15 1</ambient>
          <diffuse>0.3 0.15 0.15 1</diffuse>
          <specular>0.0 0.0 0.0 1</specular>
          <emissive>0 0 0 1</emissive>
        </material>
      </visual>
      <collision name="collision">
        <geometry>
          <cylinder>
            <radius>0.0125</radius>
            <length>0.3</length>
          </cylinder>
        </geometry>
      </collision>
    </link>
    <joint name="joint1_aab_couple_aabc" type="revolute">
      <pose relative_to="branch_aab">0 0 0.14048005464313065 0.04247379804993981 0.3692761117755387 0</pose>
      <parent>branch_aab</parent>
      <child>couple_aab_aabc</child>
      <axis>
        <xyz>1 0 0 </xyz>
        <dynamics>
          <damping>3</damping>
          <friction>0</friction>
          <spring_reference>0</spring_reference>
          <spring_stiffness>10</spring_stiffness>
        </dynamics>
        <limit>
          <effort>0</effort>
        </limit>
      </axis>
    </joint>
    <joint name="joint2_aab_couple_aabc" type="revolute">
      <pose relative_to="couple_aab_aabc">0 0 0.01 0 0 0</pose>
      <parent>couple_aab_aabc</parent>
      <child>branch_aabc</child>
      <axis>
        <xyz>0 1 0 </xyz>
        <dynamics>
          <damping>3</damping>
          <friction>0</friction>
          <spring_reference>0</spring_reference>
          <spring_stiffness>10</spring_stiffness>
        </dynamics>
        <limit>
          <effort>0</effort>
        </limit>
      </axis>
    </joint>
    <link name="couple_aab_aabc">
      <pose relative_to="joint1_aab_couple_aabc">0 0 0 0 0 0</pose>
    </link>
    <link name="apple_aabc">
      <pose relative_to="joint_aabc_apple">0 0 0 0 0 0</pose>
      <visual name="apple">
        <pose>0 0 0.04 0 0 0</pose>
        <geometry>
          <sphere>
            <radius>0.03</radius>
          </sphere>
        </geometry>
        <material>
          <ambient>0.1 0.5 0.2 1</ambient>
          <diffuse>0.1 0.4 0.2 1</diffuse>
          <specular>0.2 0.4 0.1 1</specular>
          <emissive>0 0 0 1</emissive>
        </material>
      </visual>
      <visual name="stalk">
        <pose>0 0 0.005 0 0 0</pose>
        <geometry>
          <cylinder>
            <radius>0.002</radius>
            <length>0.01</length>
          </cylinder>
        </geometry>
        <material>
          <ambient>0.4 0.2 0.1 1</ambient>
          <diffuse>0.4 0.2 0.1 1</diffuse>
          <specular>0.2 0.1 0.1 1</specular>
          <emissive>0 0 0 1</emissive>
        </material>
      </visual>
      <inertial>
        <pose>0 0 0.04 0 0 0</pose>
        <mass>0.1</mass>
        <inertia>
          <ixx>0.0005</ixx>
          <ixy>0</ixy>
          <ixz>0</ixz>
          <iyy>0.0005</iyy>
          <iyz>0</iyz>
          <izz>0.0005</izz>
        </inertia>
      </inertial>
      <collision name="collision">
        <pose>0 0 0.04 0 0 0</pose>
        <geometry>
          <sphere>
            <radius>0.03</radius>
          </sphere>
        </geometry>
      </collision>
    </link>
    <joint name="joint_aabc_apple" type="universal">
      <pose relative_to="branch_aabc">0.0125 0 0.1590976315360511 0 1.5707963267948966 0</pose>
      <parent>branch_aabc</parent>
      <child>apple_aabc</child>
      <axis>
        <xyz>0 1 0 </xyz>
        <dynamics>
          <damping>0.001</damping>
          <friction>0</friction>
          <spring_reference>0</spring_reference>
          <spring_stiffness>0.2</spring_stiffness>
        </dynamics>
        <limit>
          <effort>0</effort>
        </limit>
      </axis>
      <axis2>
        <xyz>1 0 0 </xyz>
        <dynamics>
          <damping>0.001</damping>
          <friction>0</friction>
          <spring_reference>0</spring_reference>
          <spring_stiffness>0.2</spring_stiffness>
        </dynamics>
        <limit>
          <effort>0</effort>
        </limit>
      </axis2>
    </joint>
    <link name="branch_aac">
      <pose relative_to="joint2_aa_couple_aac">0 0 0.25 0 0 0</pose>
      <visual name="visual">
        <geometry>
          <cylinder>
            <radius>0.016666666666666666</radius>
            <length>0.5</length>
          </cylinder>
        </geometry>
        <material>
          <ambient>0.3 0.15 0.15 1</ambient>
          <diffuse>0.3 0.15 0.15 1</diffuse>
          <specular>0.0 0.0 0.0 1</specular>
          <emissive>0 0 0 1</emissive>
        </material>
      </visual>
      <collision name="collision">
        <geometry>
          <cylinder>
            <radius>0.016666666666666666</radius>
            <length>0.3</length>
          </cylinder>
        </geometry>
      </collision>
    </link>
    <joint name="joint1_aa_couple_aac" type="revolute">
      <pose relative_to="branch_aa">0 0 0.12946633776369332 0.24811186981012417 0.20501373385358923 0</pose>
      <parent>branch_aa</parent>
      <child>couple_aa_aac</child>
      <axis>
        <xyz>1 0 0 </xyz>
        <dynamics>
          <damping>5</damping>
          <friction>0</friction>
          <spring_reference>0</spring_reference>
          <spring_stiffness>300</spring_stiffness>
        </dynamics>
        <limit>
          <effort>0</effort>
        </limit>
      </axis>
    </joint>
    <joint name="joint2_aa_couple_aac" type="revolute">
      <pose relative_to="couple_aa_aac">0 0 0.01 0 0 0</pose>
      <parent>couple_aa_aac</parent>
      <child>branch_aac</child>
      <axis>
        <xyz>0 1 0 </xyz>
        <dynamics>
          <damping>5</damping>
          <friction>0</friction>
          <spring_reference>0</spring_reference>
          <spring_stiffness>300</spring_stiffness>
        </dynamics>
        <limit>
          <effort>0</effort>
        </limit>
      </axis>
    </joint>
    <link name="couple_aa_aac">
      <pose relative_to="joint1_aa_couple_aac">0 0 0 0 0 0</pose>
    </link>
    <link name="apple_aac">
      <pose relative_to="joint_aac_apple">0 0 0 0 0 0</pose>
      <visual name="apple">
        <pose>0 0 0.04 0 0 0</pose>
        <geometry>
          <sphere>
            <radius>0.03</radius>
          </sphere>
        </geometry>
        <material>
          <ambient>0.1 0.5 0.2 1</ambient>
          <diffuse>0.1 0.4 0.2 1</diffuse>
          <specular>0.2 0.4 0.1 1</specular>
          <emissive>0 0 0 1</emissive>
        </material>
      </visual>
      <visual name="stalk">
        <pose>0 0 0.005 0 0 0</pose>
        <geometry>
          <cylinder>
            <radius>0.002</radius>
            <length>0.01</length>
          </cylinder>
        </geometry>
        <material>
          <ambient>0.4 0.2 0.1 1</ambient>
          <diffuse>0.4 0.2 0.1 1</diffuse>
          <specular>0.2 0.1 0.1 1</specular>
          <emissive>0 0 0 1</emissive>
        </material>
      </visual>
      <inertial>
        <pose>0 0 0.04 0 0 0</pose>
        <mass>0.1</mass>
        <inertia>
          <ixx>0.0005</ixx>
          <ixy>0</ixy>
          <ixz>0</ixz>
          <iyy>0.0005</iyy>
          <iyz>0</iyz>
          <izz>0.0005</izz>
        </inertia>
      </inertial>
      <collision name="collision">
        <pose>0 0 0.04 0 0 0</pose>
        <geometry>
          <sphere>
            <radius>0.03</radius>
          </sphere>
        </geometry>
      </collision>
    </link>
    <joint name="joint_aac_apple" type="universal">
      <pose relative_to="branch_aac">0.016666666666666666 0 -0.021684852795888027 0 1.5707963267948966 0</pose>
      <parent>branch_aac</parent>
      <child>apple_aac</child>
      <axis>
        <xyz>0 1 0 </xyz>
        <dynamics>
          <damping>0.001</damping>
          <friction>0</friction>
          <spring_reference>0</spring_reference>
          <spring_stiffness>0.2</spring_stiffness>
        </dynamics>
        <limit>
          <effort>0</effort>
        </limit>
      </axis>
      <axis2>
        <xyz>1 0 0 </xyz>
        <dynamics>
          <damping>0.001</damping>
          <friction>0</friction>
          <spring_reference>0</spring_reference>
          <spring_stiffness>0.2</spring_stiffness>
        </dynamics>
        <limit>
          <effort>0</effort>
        </limit>
      </axis2>
    </joint>
    <link name="branch_aaca">
      <pose relative_to="joint2_aac_couple_aaca">0 0 0.2 0 0 0</pose>
      <visual name="visual">
        <geometry>
          <cylinder>
            <radius>0.0125</radius>
            <length>0.4</length>
          </cylinder>
        </geometry>
        <material>
          <ambient>0.3 0.15 0.15 1</ambient>
          <diffuse>0.3 0.15 0.15 1</diffuse>
          <specular>0.0 0.0 0.0 1</specular>
          <emissive>0 0 0 1</emissive>
        </material>
      </visual>
      <collision name="collision">
        <geometry>
          <cylinder>
            <radius>0.0125</radius>
            <length>0.3</length>
          </cylinder>
        </geometry>
      </collision>
    </link>
    <joint name="joint1_aac_couple_aaca" type="revolute">
      <pose relative_to="branch_aac">0 0 0.1269405724967505 0.4010163595943236 0.26636691351933406 0</pose>
      <parent>branch_aac</parent>
      <child>couple_aac_aaca</child>
      <axis>
        <xyz>1 0 0 </xyz>
        <dynamics>
          <damping>3</damping>
          <friction>0</friction>
          <spring_reference>0</spring_reference>
          <spring_stiffness>10</spring_stiffness>
        </dynamics>
        <limit>
          <effort>0</effort>
        </limit>
      </axis>
    </joint>
    <joint name="joint2_aac_couple_aaca" type="revolute">
      <pose relative_to="couple_aac_aaca">0 0 0.01 0 0 0</pose>
      <parent>couple_aac_aaca</parent>
      <child>branch_aaca</child>
      <axis>
        <xyz>0 1 0 </xyz>
        <dynamics>
          <damping>3</damping>
          <friction>0</friction>
          <spring_reference>0</spring_reference>
          <spring_stiffness>10</spring_stiffness>
        </dynamics>
        <limit>
          <effort>0</effort>
        </limit>
      </axis>
    </joint>
    <link name="couple_aac_aaca">
      <pose relative_to="joint1_aac_couple_aaca">0 0 0 0 0 0</pose>
    </link>
    <link name="apple_aaca">
      <pose relative_to="joint_aaca_apple">0 0 0 0 0 0</pose>
      <visual name="apple">
        <pose>0 0 0.04 0 0 0</pose>
        <geometry>
          <sphere>
            <radius>0.03</radius>
          </sphere>
        </geometry>
        <material>
          <ambient>0.1 0.5 0.2 1</ambient>
          <diffuse>0.1 0.4 0.2 1</diffuse>
          <specular>0.2 0.4 0.1 1</specular>
          <emissive>0 0 0 1</emissive>
        </material>
      </visual>
      <visual name="stalk">
        <pose>0 0 0.005 0 0 0</pose>
        <geometry>
          <cylinder>
            <radius>0.002</radius>
            <length>0.01</length>
          </cylinder>
        </geometry>
        <material>
          <ambient>0.4 0.2 0.1 1</ambient>
          <diffuse>0.4 0.2 0.1 1</diffuse>
          <specular>0.2 0.1 0.1 1</specular>
          <emissive>0 0 0 1</emissive>
        </material>
      </visual>
      <inertial>
        <pose>0 0 0.04 0 0 0</pose>
        <mass>0.1</mass>
        <inertia>
          <ixx>0.0005</ixx>
          <ixy>0</ixy>
          <ixz>0</ixz>
          <iyy>0.0005</iyy>
          <iyz>0</iyz>
          <izz>0.0005</izz>
        </inertia>
      </inertial>
      <collision name="collision">
        <pose>0 0 0.04 0 0 0</pose>
        <geometry>
          <sphere>
            <radius>0.03</radius>
          </sphere>
        </geometry>
      </collision>
    </link>
    <joint name="joint_aaca_apple" type="universal">
      <pose relative_to="branch_aaca">0.0125 0 0.06029882543556633 0 1.5707963267948966 0</pose>
      <parent>branch_aaca</parent>
      <child>apple_aaca</child>
      <axis>
        <xyz>0 1 0 </xyz>
        <dynamics>
          <damping>0.001</damping>
          <friction>0</friction>
          <spring_reference>0</spring_reference>
          <spring_stiffness>0.2</spring_stiffness>
        </dynamics>
        <limit>
          <effort>0</effort>
        </limit>
      </axis>
      <axis2>
        <xyz>1 0 0 </xyz>
        <dynamics>
          <damping>0.001</damping>
          <friction>0</friction>
          <spring_reference>0</spring_reference>
          <spring_stiffness>0.2</spring_stiffness>
        </dynamics>
        <limit>
          <effort>0</effort>
        </limit>
      </axis2>
    </joint>
    <link name="branch_aacb">
      <pose relative_to="joint2_aac_couple_aacb">0 0 0.2 0 0 0</pose>
      <visual name="visual">
        <geometry>
          <cylinder>
            <radius>0.0125</radius>
            <length>0.4</length>
          </cylinder>
        </geometry>
        <material>
          <ambient>0.3 0.15 0.15 1</ambient>
          <diffuse>0.3 0.15 0.15 1</diffuse>
          <specular>0.0 0.0 0.0 1</specular>
          <emissive>0 0 0 1</emissive>
        </material>
      </visual>
      <collision name="collision">
        <geometry>
          <cylinder>
            <radius>0.0125</radius>
            <length>0.3</length>
          </cylinder>
        </geometry>
      </collision>
    </link>
    <joint name="joint1_aac_couple_aacb" type="revolute">
      <pose relative_to="branch_aac">0 0 0.11966198733611438 -0.6739543706803992 0.3172275277652213 0</pose>
      <parent>branch_aac</parent>
      <child>couple_aac_aacb</child>
      <axis>
        <xyz>1 0 0 </xyz>
        <dynamics>
          <damping>3</damping>
          <friction>0</friction>
          <spring_reference>0</spring_reference>
          <spring_stiffness>10</spring_stiffness>
        </dynamics>
        <limit>
          <effort>0</effort>
        </limit>
      </axis>
    </joint>
    <joint name="joint2_aac_couple_aacb" type="revolute">
      <pose relative_to="couple_aac_aacb">0 0 0.01 0 0 0</pose>
      <parent>couple_aac_aacb</parent>
      <child>branch_aacb</child>
      <axis>
        <xyz>0 1 0 </xyz>
        <dynamics>
          <damping>3</damping>
          <friction>0</friction>
          <spring_reference>0</spring_reference>
          <spring_stiffness>10</spring_stiffness>
        </dynamics>
        <limit>
          <effort>0</effort>
        </limit>
      </axis>
    </joint>
    <link name="couple_aac_aacb">
      <pose relative_to="joint1_aac_couple_aacb">0 0 0 0 0 0</pose>
    </link>
    <link name="apple_aacb">
      <pose relative_to="joint_aacb_apple">0 0 0 0 0 0</pose>
      <visual name="apple">
        <pose>0 0 0.04 0 0 0</pose>
        <geometry>
          <sphere>
            <radius>0.03</radius>
          </sphere>
        </geometry>
        <material>
          <ambient>0.1 0.5 0.2 1</ambient>
          <diffuse>0.1 0.4 0.2 1</diffuse>
          <specular>0.2 0.4 0.1 1</specular>
          <emissive>0 0 0 1</emissive>
        </material>
      </visual>
      <visual name="stalk">
        <pose>0 0 0.005 0 0 0</pose>
        <geometry>
          <cylinder>
            <radius>0.002</radius>
            <length>0.01</length>
          </cylinder>
        </geometry>
        <material>
          <ambient>0.4 0.2 0.1 1</ambient>
          <diffuse>0.4 0.2 0.1 1</diffuse>
          <specular>0.2 0.1 0.1 1</specular>
          <emissive>0 0 0 1</emissive>
        </material>
      </visual>
      <inertial>
        <pose>0 0 0.04 0 0 0</pose>
        <mass>0.1</mass>
        <inertia>
          <ixx>0.0005</ixx>
          <ixy>0</ixy>
          <ixz>0</ixz>
          <iyy>0.0005</iyy>
          <iyz>0</iyz>
          <izz>0.0005</izz>
        </inertia>
      </inertial>
      <collision name="collision">
        <pose>0 0 0.04 0 0 0</pose>
        <geometry>
          <sphere>
            <radius>0.03</radius>
          </sphere>
        </geometry>
      </collision>
    </link>
    <joint name="joint_aacb_apple" type="universal">
      <pose relative_to="branch_aacb">0.0125 0 -0.007546705437092405 0 1.5707963267948966 0</pose>
      <parent>branch_aacb</parent>
      <child>apple_aacb</child>
      <axis>
        <xyz>0 1 0 </xyz>
        <dynamics>
          <damping>0.001</damping>
          <friction>0</friction>
          <spring_reference>0</spring_reference>
          <spring_stiffness>0.2</spring_stiffness>
        </dynamics>
        <limit>
          <effort>0</effort>
        </limit>
      </axis>
      <axis2>
        <xyz>1 0 0 </xyz>
        <dynamics>
          <damping>0.001</damping>
          <friction>0</friction>
          <spring_reference>0</spring_reference>
          <spring_stiffness>0.2</spring_stiffness>
        </dynamics>
        <limit>
          <effort>0</effort>
        </limit>
      </axis2>
    </joint>
    <link name="branch_aacc">
      <pose relative_to="joint2_aac_couple_aacc">0 0 0.2 0 0 0</pose>
      <visual name="visual">
        <geometry>
          <cylinder>
            <radius>0.0125</radius>
            <length>0.4</length>
          </cylinder>
        </geometry>
        <material>
          <ambient>0.3 0.15 0.15 1</ambient>
          <diffuse>0.3 0.15 0.15 1</diffuse>
          <specular>0.0 0.0 0.0 1</specular>
          <emissive>0 0 0 1</emissive>
        </material>
      </visual>
      <collision name="collision">
        <geometry>
          <cylinder>
            <radius>0.0125</radius>
            <length>0.3</length>
          </cylinder>
        </geometry>
      </collision>
    </link>
    <joint name="joint1_aac_couple_aacc" type="revolute">
      <pose relative_to="branch_aac">0 0 0.15650884701859846 0.5599294014654523 0.20360495515112895 0</pose>
      <parent>branch_aac</parent>
      <child>couple_aac_aacc</child>
      <axis>
        <xyz>1 0 0 </xyz>
        <dynamics>
          <damping>3</damping>
          <friction>0</friction>
          <spring_reference>0</spring_reference>
          <spring_stiffness>10</spring_stiffness>
        </dynamics>
        <limit>
          <effort>0</effort>
        </limit>
      </axis>
    </joint>
    <joint name="joint2_aac_couple_aacc" type="revolute">
      <pose relative_to="couple_aac_aacc">0 0 0.01 0 0 0</pose>
      <parent>couple_aac_aacc</parent>
      <child>branch_aacc</child>
      <axis>
        <xyz>0 1 0 </xyz>
        <dynamics>
          <damping>3</damping>
          <friction>0</friction>
          <spring_reference>0</spring_reference>
          <spring_stiffness>10</spring_stiffness>
        </dynamics>
        <limit>
          <effort>0</effort>
        </limit>
      </axis>
    </joint>
    <link name="couple_aac_aacc">
      <pose relative_to="joint1_aac_couple_aacc">0 0 0 0 0 0</pose>
    </link>
    <link name="apple_aacc">
      <pose relative_to="joint_aacc_apple">0 0 0 0 0 0</pose>
      <visual name="apple">
        <pose>0 0 0.04 0 0 0</pose>
        <geometry>
          <sphere>
            <radius>0.03</radius>
          </sphere>
        </geometry>
        <material>
          <ambient>0.1 0.5 0.2 1</ambient>
          <diffuse>0.1 0.4 0.2 1</diffuse>
          <specular>0.2 0.4 0.1 1</specular>
          <emissive>0 0 0 1</emissive>
        </material>
      </visual>
      <visual name="stalk">
        <pose>0 0 0.005 0 0 0</pose>
        <geometry>
          <cylinder>
            <radius>0.002</radius>
            <length>0.01</length>
          </cylinder>
        </geometry>
        <material>
          <ambient>0.4 0.2 0.1 1</ambient>
          <diffuse>0.4 0.2 0.1 1</diffuse>
          <specular>0.2 0.1 0.1 1</specular>
          <emissive>0 0 0 1</emissive>
        </material>
      </visual>
      <inertial>
        <pose>0 0 0.04 0 0 0</pose>
        <mass>0.1</mass>
        <inertia>
          <ixx>0.0005</ixx>
          <ixy>0</ixy>
          <ixz>0</ixz>
          <iyy>0.0005</iyy>
          <iyz>0</iyz>
          <izz>0.0005</izz>
        </inertia>
      </inertial>
      <collision name="collision">
        <pose>0 0 0.04 0 0 0</pose>
        <geometry>
          <sphere>
            <radius>0.03</radius>
          </sphere>
        </geometry>
      </collision>
    </link>
    <joint name="joint_aacc_apple" type="universal">
      <pose relative_to="branch_aacc">0.0125 0 -0.004876077911191393 0 1.5707963267948966 0</pose>
      <parent>branch_aacc</parent>
      <child>apple_aacc</child>
      <axis>
        <xyz>0 1 0 </xyz>
        <dynamics>
          <damping>0.001</damping>
          <friction>0</friction>
          <spring_reference>0</spring_reference>
          <spring_stiffness>0.2</spring_stiffness>
        </dynamics>
        <limit>
          <effort>0</effort>
        </limit>
      </axis>
      <axis2>
        <xyz>1 0 0 </xyz>
        <dynamics>
          <damping>0.001</damping>
          <friction>0</friction>
          <spring_reference>0</spring_reference>
          <spring_stiffness>0.2</spring_stiffness>
        </dynamics>
        <limit>
          <effort>0</effort>
        </limit>
      </axis2>
    </joint>
  </model>
</sdf>
